
Internal Server Error: /index/
Traceback (most recent call last):
  File "C:\Users\uqwzhon4\Anaconda3\envs\orgdb_env\Lib\site-packages\django\core\handlers\exception.py", line 55, in inner
    response = get_response(request)
               ^^^^^^^^^^^^^^^^^^^^^
  File "C:\Users\uqwzhon4\Anaconda3\envs\orgdb_env\Lib\site-packages\django\core\handlers\base.py", line 197, in _get_response
    response = wrapped_callback(request, *callback_args, **callback_kwargs)
               ^^^^^^^^^^^^^^^^^^^^^^^^^^^^^^^^^^^^^^^^^^^^^^^^^^^^^^^^^^^^
  File "C:\Users\uqwzhon4\Anaconda3\envs\orgdb_env\Lib\site-packages\django\contrib\auth\decorators.py", line 23, in _wrapped_view
    return view_func(request, *args, **kwargs)
           ^^^^^^^^^^^^^^^^^^^^^^^^^^^^^^^^^^^
  File "C:\Users\uqwzhon4\project\adjCOADD\apputil\views.py", line 34, in index
    return render(req, 'dorganism/home.html', {'objects_org': object_1, 'objects_taxo':object_2,})
           ^^^^^^^^^^^^^^^^^^^^^^^^^^^^^^^^^^^^^^^^^^^^^^^^^^^^^^^^^^^^^^^^^^^^^^^^^^^^^^^^^^^^^^^
  File "C:\Users\uqwzhon4\Anaconda3\envs\orgdb_env\Lib\site-packages\django\shortcuts.py", line 24, in render
    content = loader.render_to_string(template_name, context, request, using=using)
              ^^^^^^^^^^^^^^^^^^^^^^^^^^^^^^^^^^^^^^^^^^^^^^^^^^^^^^^^^^^^^^^^^^^^^
  File "C:\Users\uqwzhon4\Anaconda3\envs\orgdb_env\Lib\site-packages\django\template\loader.py", line 62, in render_to_string
    return template.render(context, request)
           ^^^^^^^^^^^^^^^^^^^^^^^^^^^^^^^^^
  File "C:\Users\uqwzhon4\Anaconda3\envs\orgdb_env\Lib\site-packages\django\template\backends\django.py", line 62, in render
    return self.template.render(context)
           ^^^^^^^^^^^^^^^^^^^^^^^^^^^^^
  File "C:\Users\uqwzhon4\Anaconda3\envs\orgdb_env\Lib\site-packages\django\template\base.py", line 175, in render
    return self._render(context)
           ^^^^^^^^^^^^^^^^^^^^^
  File "C:\Users\uqwzhon4\Anaconda3\envs\orgdb_env\Lib\site-packages\django\template\base.py", line 167, in _render
    return self.nodelist.render(context)
           ^^^^^^^^^^^^^^^^^^^^^^^^^^^^^
  File "C:\Users\uqwzhon4\Anaconda3\envs\orgdb_env\Lib\site-packages\django\template\base.py", line 1005, in render
    return SafeString("".join([node.render_annotated(context) for node in self]))
                              ^^^^^^^^^^^^^^^^^^^^^^^^^^^^^^^^^^^^^^^^^^^^^^^^^
  File "C:\Users\uqwzhon4\Anaconda3\envs\orgdb_env\Lib\site-packages\django\template\base.py", line 1005, in <listcomp>
    return SafeString("".join([node.render_annotated(context) for node in self]))
                               ^^^^^^^^^^^^^^^^^^^^^^^^^^^^^^
  File "C:\Users\uqwzhon4\Anaconda3\envs\orgdb_env\Lib\site-packages\django\template\base.py", line 966, in render_annotated
    return self.render(context)
           ^^^^^^^^^^^^^^^^^^^^
  File "C:\Users\uqwzhon4\Anaconda3\envs\orgdb_env\Lib\site-packages\django\template\loader_tags.py", line 157, in render
    return compiled_parent._render(context)
           ^^^^^^^^^^^^^^^^^^^^^^^^^^^^^^^^
  File "C:\Users\uqwzhon4\Anaconda3\envs\orgdb_env\Lib\site-packages\django\template\base.py", line 167, in _render
    return self.nodelist.render(context)
           ^^^^^^^^^^^^^^^^^^^^^^^^^^^^^
  File "C:\Users\uqwzhon4\Anaconda3\envs\orgdb_env\Lib\site-packages\django\template\base.py", line 1005, in render
    return SafeString("".join([node.render_annotated(context) for node in self]))
                              ^^^^^^^^^^^^^^^^^^^^^^^^^^^^^^^^^^^^^^^^^^^^^^^^^
  File "C:\Users\uqwzhon4\Anaconda3\envs\orgdb_env\Lib\site-packages\django\template\base.py", line 1005, in <listcomp>
    return SafeString("".join([node.render_annotated(context) for node in self]))
                               ^^^^^^^^^^^^^^^^^^^^^^^^^^^^^^
  File "C:\Users\uqwzhon4\Anaconda3\envs\orgdb_env\Lib\site-packages\django\template\base.py", line 966, in render_annotated
    return self.render(context)
           ^^^^^^^^^^^^^^^^^^^^
  File "C:\Users\uqwzhon4\Anaconda3\envs\orgdb_env\Lib\site-packages\django\template\loader_tags.py", line 208, in render
    return template.render(context)
           ^^^^^^^^^^^^^^^^^^^^^^^^
  File "C:\Users\uqwzhon4\Anaconda3\envs\orgdb_env\Lib\site-packages\django\template\base.py", line 177, in render
    return self._render(context)
           ^^^^^^^^^^^^^^^^^^^^^
  File "C:\Users\uqwzhon4\Anaconda3\envs\orgdb_env\Lib\site-packages\django\template\base.py", line 167, in _render
    return self.nodelist.render(context)
           ^^^^^^^^^^^^^^^^^^^^^^^^^^^^^
  File "C:\Users\uqwzhon4\Anaconda3\envs\orgdb_env\Lib\site-packages\django\template\base.py", line 1005, in render
    return SafeString("".join([node.render_annotated(context) for node in self]))
                              ^^^^^^^^^^^^^^^^^^^^^^^^^^^^^^^^^^^^^^^^^^^^^^^^^
  File "C:\Users\uqwzhon4\Anaconda3\envs\orgdb_env\Lib\site-packages\django\template\base.py", line 1005, in <listcomp>
    return SafeString("".join([node.render_annotated(context) for node in self]))
                               ^^^^^^^^^^^^^^^^^^^^^^^^^^^^^^
  File "C:\Users\uqwzhon4\Anaconda3\envs\orgdb_env\Lib\site-packages\django\template\base.py", line 966, in render_annotated
    return self.render(context)
           ^^^^^^^^^^^^^^^^^^^^
  File "C:\Users\uqwzhon4\Anaconda3\envs\orgdb_env\Lib\site-packages\django\template\defaulttags.py", line 322, in render
    return nodelist.render(context)
           ^^^^^^^^^^^^^^^^^^^^^^^^
  File "C:\Users\uqwzhon4\Anaconda3\envs\orgdb_env\Lib\site-packages\django\template\base.py", line 1005, in render
    return SafeString("".join([node.render_annotated(context) for node in self]))
                              ^^^^^^^^^^^^^^^^^^^^^^^^^^^^^^^^^^^^^^^^^^^^^^^^^
  File "C:\Users\uqwzhon4\Anaconda3\envs\orgdb_env\Lib\site-packages\django\template\base.py", line 1005, in <listcomp>
    return SafeString("".join([node.render_annotated(context) for node in self]))
                               ^^^^^^^^^^^^^^^^^^^^^^^^^^^^^^
  File "C:\Users\uqwzhon4\Anaconda3\envs\orgdb_env\Lib\site-packages\django\template\base.py", line 966, in render_annotated
    return self.render(context)
           ^^^^^^^^^^^^^^^^^^^^
  File "C:\Users\uqwzhon4\Anaconda3\envs\orgdb_env\Lib\site-packages\django\template\defaulttags.py", line 472, in render
    url = reverse(view_name, args=args, kwargs=kwargs, current_app=current_app)
          ^^^^^^^^^^^^^^^^^^^^^^^^^^^^^^^^^^^^^^^^^^^^^^^^^^^^^^^^^^^^^^^^^^^^^
  File "C:\Users\uqwzhon4\Anaconda3\envs\orgdb_env\Lib\site-packages\django\urls\base.py", line 88, in reverse
    return resolver._reverse_with_prefix(view, prefix, *args, **kwargs)
           ^^^^^^^^^^^^^^^^^^^^^^^^^^^^^^^^^^^^^^^^^^^^^^^^^^^^^^^^^^^^
  File "C:\Users\uqwzhon4\Anaconda3\envs\orgdb_env\Lib\site-packages\django\urls\resolvers.py", line 828, in _reverse_with_prefix
    raise NoReverseMatch(msg)
django.urls.exceptions.NoReverseMatch: Reverse for 'home' not found. 'home' is not a valid view function or pattern name.
"GET /index/ HTTP/1.1" 500 197565
Not Found: /favicon.ico
"GET /favicon.ico HTTP/1.1" 404 10859
Not Found: /favicon.ico
"GET /favicon.ico HTTP/1.1" 404 10859
"GET /static/images/AMD00002.svg HTTP/1.1" 404 1917
"GET /static/images/AMD00005.svg HTTP/1.1" 404 1917
"GET /static/images/AMD00004.svg HTTP/1.1" 404 1917
"GET /static/images/AMD00007.svg HTTP/1.1" 404 1917
"GET /static/images/AMD00006.svg HTTP/1.1" 404 1917
"GET /static/images/AMD00003.svg HTTP/1.1" 404 1917
"GET /static/images/AMD00178.svg HTTP/1.1" 404 1917
"GET /static/images/AMD00008.svg HTTP/1.1" 404 1917
"GET /static/images/AMD00009.svg HTTP/1.1" 404 1917
"GET /static/images/AMD00022.svg HTTP/1.1" 404 1917
"GET /static/images/AMD00011.svg HTTP/1.1" 404 1917
"GET /static/images/AMD00017.svg HTTP/1.1" 404 1917
"GET /static/images/AMD00012.svg HTTP/1.1" 404 1917
"GET /static/images/AMD00010.svg HTTP/1.1" 404 1917
"GET /static/images/AMD00020.svg HTTP/1.1" 404 1917
"GET /static/images/AMD00014.svg HTTP/1.1" 404 1917
"GET /static/images/AMD00019.svg HTTP/1.1" 404 1917
"GET /static/images/AMD00032.svg HTTP/1.1" 404 1917
"GET /static/images/AMD00026.svg HTTP/1.1" 404 1917
"GET /static/images/AMD00031.svg HTTP/1.1" 404 1917
"GET /static/images/AMD00023.svg HTTP/1.1" 404 1917
"GET /static/images/AMD00013.svg HTTP/1.1" 404 1917
"GET /static/images/AMD00027.svg HTTP/1.1" 404 1917
"GET /static/images/AMD00030.svg HTTP/1.1" 404 1917
"GET /static/images/AMD00216.svg HTTP/1.1" 404 1917
"GET /static/images/AMD00015.svg HTTP/1.1" 404 1917
"GET /static/images/AMD00021.svg HTTP/1.1" 404 1917
"GET /static/images/AMD00028.svg HTTP/1.1" 404 1917
"GET /static/images/AMD00025.svg HTTP/1.1" 404 1917
"GET /static/images/AMD00016.svg HTTP/1.1" 404 1917
"GET /static/images/AMD00219.svg HTTP/1.1" 404 1917
"GET /static/images/AMD00018.svg HTTP/1.1" 404 1917
"GET /static/images/AMD00024.svg HTTP/1.1" 404 1917
"GET /static/images/AMD00029.svg HTTP/1.1" 404 1917
"GET /static/images/AMD00034.svg HTTP/1.1" 404 1917
"GET /static/images/AMD00179.svg HTTP/1.1" 404 1917
"GET /static/images/AMD00033.svg HTTP/1.1" 404 1917
"GET /static/images/AMD00220.svg HTTP/1.1" 404 1917
"GET /static/images/AMD00035.svg HTTP/1.1" 404 1917
"GET /static/images/AMD00036.svg HTTP/1.1" 404 1917
"GET /static/images/AMD00038.svg HTTP/1.1" 404 1917
"GET /static/images/AMD00214.svg HTTP/1.1" 404 1917
"GET /static/images/AMD00037.svg HTTP/1.1" 404 1917
"GET /static/images/AMD00039.svg HTTP/1.1" 404 1917
"GET /static/images/AMD00042.svg HTTP/1.1" 404 1917
"GET /static/images/AMD00043.svg HTTP/1.1" 404 1917
"GET /static/images/AMD00040.svg HTTP/1.1" 404 1917
"GET /static/images/AMD00041.svg HTTP/1.1" 404 1917
"GET /static/images/AMD00045.svg HTTP/1.1" 404 1917
"GET /static/images/AMD00044.svg HTTP/1.1" 404 1917
"GET /static/images/AMD00002.svg HTTP/1.1" 404 1917
"GET /static/images/AMD00007.svg HTTP/1.1" 404 1917
"GET /static/images/AMD00004.svg HTTP/1.1" 404 1917
"GET /static/images/AMD00003.svg HTTP/1.1" 404 1917
"GET /static/images/AMD00005.svg HTTP/1.1" 404 1917
"GET /static/images/AMD00006.svg HTTP/1.1" 404 1917
"GET /static/images/AMD00008.svg HTTP/1.1" 404 1917
"GET /static/images/AMD00178.svg HTTP/1.1" 404 1917
"GET /static/images/AMD00010.svg HTTP/1.1" 404 1917
"GET /static/images/AMD00009.svg HTTP/1.1" 404 1917
"GET /static/images/AMD00011.svg HTTP/1.1" 404 1917
"GET /static/images/AMD00031.svg HTTP/1.1" 404 1917
"GET /static/images/AMD00216.svg HTTP/1.1" 404 1917
"GET /static/images/AMD00024.svg HTTP/1.1" 404 1917
"GET /static/images/AMD00019.svg HTTP/1.1" 404 1917
"GET /static/images/AMD00021.svg HTTP/1.1" 404 1917
"GET /static/images/AMD00018.svg HTTP/1.1" 404 1917
"GET /static/images/AMD00013.svg HTTP/1.1" 404 1917
"GET /static/images/AMD00025.svg HTTP/1.1" 404 1917
"GET /static/images/AMD00023.svg HTTP/1.1" 404 1917
"GET /static/images/AMD00022.svg HTTP/1.1" 404 1917
"GET /static/images/AMD00032.svg HTTP/1.1" 404 1917
"GET /static/images/AMD00026.svg HTTP/1.1" 404 1917
"GET /static/images/AMD00012.svg HTTP/1.1" 404 1917
"GET /static/images/AMD00028.svg HTTP/1.1" 404 1917
"GET /static/images/AMD00020.svg HTTP/1.1" 404 1917
"GET /static/images/AMD00029.svg HTTP/1.1" 404 1917
"GET /static/images/AMD00033.svg HTTP/1.1" 404 1917
"GET /static/images/AMD00027.svg HTTP/1.1" 404 1917
"GET /static/images/AMD00219.svg HTTP/1.1" 404 1917
"GET /static/images/AMD00017.svg HTTP/1.1" 404 1917
"GET /static/images/AMD00179.svg HTTP/1.1" 404 1917
"GET /static/images/AMD00014.svg HTTP/1.1" 404 1917
"GET /static/images/AMD00030.svg HTTP/1.1" 404 1917
"GET /static/images/AMD00015.svg HTTP/1.1" 404 1917
"GET /static/images/AMD00035.svg HTTP/1.1" 404 1917
"GET /static/images/AMD00034.svg HTTP/1.1" 404 1917
"GET /static/images/AMD00016.svg HTTP/1.1" 404 1917
"GET /static/images/AMD00220.svg HTTP/1.1" 404 1917
"GET /static/images/AMD00036.svg HTTP/1.1" 404 1917
"GET /static/images/AMD00037.svg HTTP/1.1" 404 1917
"GET /static/images/AMD00039.svg HTTP/1.1" 404 1917
"GET /static/images/AMD00214.svg HTTP/1.1" 404 1917
"GET /static/images/AMD00038.svg HTTP/1.1" 404 1917
"GET /static/images/AMD00040.svg HTTP/1.1" 404 1917
"GET /static/images/AMD00041.svg HTTP/1.1" 404 1917
"GET /static/images/AMD00042.svg HTTP/1.1" 404 1917
"GET /static/images/AMD00043.svg HTTP/1.1" 404 1917
"GET /static/images/AMD00044.svg HTTP/1.1" 404 1917
"GET /static/images/AMD00045.svg HTTP/1.1" 404 1917
Internal Server Error: /user_list/
Traceback (most recent call last):
  File "/home/wz/anaconda3/envs/coadd_env/lib/python3.10/site-packages/django/core/handlers/exception.py", line 55, in inner
    response = get_response(request)
  File "/home/wz/anaconda3/envs/coadd_env/lib/python3.10/site-packages/django/core/handlers/base.py", line 197, in _get_response
    response = wrapped_callback(request, *callback_args, **callback_kwargs)
  File "/home/wz/anaconda3/envs/coadd_env/lib/python3.10/site-packages/django/views/generic/base.py", line 103, in view
    return self.dispatch(request, *args, **kwargs)
  File "/home/wz/anaconda3/envs/coadd_env/lib/python3.10/site-packages/django/contrib/auth/mixins.py", line 73, in dispatch
    return super().dispatch(request, *args, **kwargs)
  File "/home/wz/anaconda3/envs/coadd_env/lib/python3.10/site-packages/django/views/generic/base.py", line 142, in dispatch
    return handler(request, *args, **kwargs)
  File "/home/wz/anaconda3/envs/coadd_env/lib/python3.10/site-packages/django/views/generic/list.py", line 154, in get
    self.object_list = self.get_queryset()
  File "/home/wz/adjCOADD/apputil/utils.py", line 217, in get_queryset
    return self.filterset.qs.distinct()
  File "/home/wz/adjCOADD/apputil/utils.py", line 159, in qs
    return parent.filter(astatus__gte=0)
  File "/home/wz/anaconda3/envs/coadd_env/lib/python3.10/site-packages/django/db/models/query.py", line 1420, in filter
    return self._filter_or_exclude(False, args, kwargs)
  File "/home/wz/anaconda3/envs/coadd_env/lib/python3.10/site-packages/django/db/models/query.py", line 1438, in _filter_or_exclude
    clone._filter_or_exclude_inplace(negate, args, kwargs)
  File "/home/wz/anaconda3/envs/coadd_env/lib/python3.10/site-packages/django/db/models/query.py", line 1445, in _filter_or_exclude_inplace
    self._query.add_q(Q(*args, **kwargs))
  File "/home/wz/anaconda3/envs/coadd_env/lib/python3.10/site-packages/django/db/models/sql/query.py", line 1532, in add_q
    clause, _ = self._add_q(q_object, self.used_aliases)
  File "/home/wz/anaconda3/envs/coadd_env/lib/python3.10/site-packages/django/db/models/sql/query.py", line 1562, in _add_q
    child_clause, needed_inner = self.build_filter(
  File "/home/wz/anaconda3/envs/coadd_env/lib/python3.10/site-packages/django/db/models/sql/query.py", line 1407, in build_filter
    lookups, parts, reffed_expression = self.solve_lookup_type(arg)
  File "/home/wz/anaconda3/envs/coadd_env/lib/python3.10/site-packages/django/db/models/sql/query.py", line 1217, in solve_lookup_type
    _, field, _, lookup_parts = self.names_to_path(lookup_splitted, self.get_meta())
  File "/home/wz/anaconda3/envs/coadd_env/lib/python3.10/site-packages/django/db/models/sql/query.py", line 1709, in names_to_path
    raise FieldError(
django.core.exceptions.FieldError: Cannot resolve keyword 'astatus' into field. Choices are: applicationlog, date_joined, department, dictionary_acreated_by, dictionary_adeleted_by, dictionary_aupdated_by, drug_acreated_by, drug_adeleted_by, drug_aupdated_by, email, first_name, group, groups, initials, is_active, is_appuser, is_staff, is_superuser, last_login, last_name, logentry, name, organisation, organism_Biologist, organism_acreated_by, organism_adeleted_by, organism_aupdated_by, organism_batch_Biologist, organism_batch_acreated_by, organism_batch_adeleted_by, organism_batch_aupdated_by, organism_culture_Biologist, organism_culture_acreated_by, organism_culture_adeleted_by, organism_culture_aupdated_by, orgbatch_stock_Biologist, orgbatch_stock_acreated_by, orgbatch_stock_adeleted_by, orgbatch_stock_aupdated_by, password, permission, phone, taxonomy_acreated_by, taxonomy_adeleted_by, taxonomy_aupdated_by, user_permissions, username, vitek_ast_acreated_by, vitek_ast_adeleted_by, vitek_ast_aupdated_by, vitek_card_acreated_by, vitek_card_adeleted_by, vitek_card_aupdated_by, vitek_id_acreated_by, vitek_id_adeleted_by, vitek_id_aupdated_by
"GET /user_list/ HTTP/1.1" 500 143435
Not Found: /favicon.ico
"GET /favicon.ico HTTP/1.1" 404 10859
Internal Server Error: /user_list/
Traceback (most recent call last):
  File "/home/wz/anaconda3/envs/coadd_env/lib/python3.10/site-packages/django/core/handlers/exception.py", line 55, in inner
    response = get_response(request)
  File "/home/wz/anaconda3/envs/coadd_env/lib/python3.10/site-packages/django/core/handlers/base.py", line 197, in _get_response
    response = wrapped_callback(request, *callback_args, **callback_kwargs)
  File "/home/wz/anaconda3/envs/coadd_env/lib/python3.10/site-packages/django/views/generic/base.py", line 103, in view
    return self.dispatch(request, *args, **kwargs)
  File "/home/wz/anaconda3/envs/coadd_env/lib/python3.10/site-packages/django/contrib/auth/mixins.py", line 73, in dispatch
    return super().dispatch(request, *args, **kwargs)
  File "/home/wz/anaconda3/envs/coadd_env/lib/python3.10/site-packages/django/views/generic/base.py", line 142, in dispatch
    return handler(request, *args, **kwargs)
  File "/home/wz/anaconda3/envs/coadd_env/lib/python3.10/site-packages/django/views/generic/list.py", line 174, in get
    context = self.get_context_data()
  File "/home/wz/adjCOADD/apputil/utils.py", line 228, in get_context_data
    context['fields']=self.model.get_fields(fields=self.model_fields)
AttributeError: type object 'ApplicationUser' has no attribute 'get_fields'
"GET /user_list/ HTTP/1.1" 500 93070
Internal Server Error: /user_list/
Traceback (most recent call last):
  File "/home/wz/anaconda3/envs/coadd_env/lib/python3.10/site-packages/django/core/handlers/exception.py", line 55, in inner
    response = get_response(request)
  File "/home/wz/anaconda3/envs/coadd_env/lib/python3.10/site-packages/django/core/handlers/base.py", line 197, in _get_response
    response = wrapped_callback(request, *callback_args, **callback_kwargs)
  File "/home/wz/anaconda3/envs/coadd_env/lib/python3.10/site-packages/django/views/generic/base.py", line 103, in view
    return self.dispatch(request, *args, **kwargs)
  File "/home/wz/anaconda3/envs/coadd_env/lib/python3.10/site-packages/django/contrib/auth/mixins.py", line 73, in dispatch
    return super().dispatch(request, *args, **kwargs)
  File "/home/wz/anaconda3/envs/coadd_env/lib/python3.10/site-packages/django/views/generic/base.py", line 142, in dispatch
    return handler(request, *args, **kwargs)
  File "/home/wz/anaconda3/envs/coadd_env/lib/python3.10/site-packages/django/views/generic/list.py", line 174, in get
    context = self.get_context_data()
  File "/home/wz/adjCOADD/apputil/utils.py", line 228, in get_context_data
    context['fields']=self.model.get_fields(fields=self.model_fields)
AttributeError: type object 'ApplicationUser' has no attribute 'get_fields'
"GET /user_list/ HTTP/1.1" 500 93070
Internal Server Error: /user_list/
Traceback (most recent call last):
  File "/home/wz/anaconda3/envs/coadd_env/lib/python3.10/site-packages/django/core/handlers/exception.py", line 55, in inner
    response = get_response(request)
  File "/home/wz/anaconda3/envs/coadd_env/lib/python3.10/site-packages/django/core/handlers/base.py", line 197, in _get_response
    response = wrapped_callback(request, *callback_args, **callback_kwargs)
  File "/home/wz/anaconda3/envs/coadd_env/lib/python3.10/site-packages/django/views/generic/base.py", line 103, in view
    return self.dispatch(request, *args, **kwargs)
  File "/home/wz/anaconda3/envs/coadd_env/lib/python3.10/site-packages/django/contrib/auth/mixins.py", line 73, in dispatch
    return super().dispatch(request, *args, **kwargs)
  File "/home/wz/anaconda3/envs/coadd_env/lib/python3.10/site-packages/django/views/generic/base.py", line 142, in dispatch
    return handler(request, *args, **kwargs)
  File "/home/wz/anaconda3/envs/coadd_env/lib/python3.10/site-packages/django/views/generic/list.py", line 174, in get
    context = self.get_context_data()
  File "/home/wz/adjCOADD/apputil/utils.py", line 229, in get_context_data
    context['model_fields']=self.model.get_modelfields(fields=self.model_fields)
AttributeError: type object 'ApplicationUser' has no attribute 'get_modelfields'
"GET /user_list/ HTTP/1.1" 500 93365
Internal Server Error: /user_list/
Traceback (most recent call last):
  File "/home/wz/anaconda3/envs/coadd_env/lib/python3.10/site-packages/django/core/handlers/exception.py", line 55, in inner
    response = get_response(request)
  File "/home/wz/anaconda3/envs/coadd_env/lib/python3.10/site-packages/django/core/handlers/base.py", line 197, in _get_response
    response = wrapped_callback(request, *callback_args, **callback_kwargs)
  File "/home/wz/anaconda3/envs/coadd_env/lib/python3.10/site-packages/django/views/generic/base.py", line 103, in view
    return self.dispatch(request, *args, **kwargs)
  File "/home/wz/anaconda3/envs/coadd_env/lib/python3.10/site-packages/django/contrib/auth/mixins.py", line 73, in dispatch
    return super().dispatch(request, *args, **kwargs)
  File "/home/wz/anaconda3/envs/coadd_env/lib/python3.10/site-packages/django/views/generic/base.py", line 142, in dispatch
    return handler(request, *args, **kwargs)
  File "/home/wz/anaconda3/envs/coadd_env/lib/python3.10/site-packages/django/views/generic/list.py", line 154, in get
    self.object_list = self.get_queryset()
  File "/home/wz/adjCOADD/apputil/utils.py", line 217, in get_queryset
    return self.filterset.qs.distinct()
  File "/home/wz/anaconda3/envs/coadd_env/lib/python3.10/site-packages/django_filters/filterset.py", line 230, in qs
    qs = self.filter_queryset(qs)
  File "/home/wz/anaconda3/envs/coadd_env/lib/python3.10/site-packages/django_filters/filterset.py", line 213, in filter_queryset
    queryset = self.filters[name].filter(queryset, value)
  File "/home/wz/anaconda3/envs/coadd_env/lib/python3.10/site-packages/django_filters/filters.py", line 179, in filter
    return super().filter(qs, value)
  File "/home/wz/anaconda3/envs/coadd_env/lib/python3.10/site-packages/django_filters/filters.py", line 158, in filter
    qs = self.get_method(qs)(**{lookup: value})
  File "/home/wz/anaconda3/envs/coadd_env/lib/python3.10/site-packages/django/db/models/query.py", line 1420, in filter
    return self._filter_or_exclude(False, args, kwargs)
  File "/home/wz/anaconda3/envs/coadd_env/lib/python3.10/site-packages/django/db/models/query.py", line 1438, in _filter_or_exclude
    clone._filter_or_exclude_inplace(negate, args, kwargs)
  File "/home/wz/anaconda3/envs/coadd_env/lib/python3.10/site-packages/django/db/models/query.py", line 1445, in _filter_or_exclude_inplace
    self._query.add_q(Q(*args, **kwargs))
  File "/home/wz/anaconda3/envs/coadd_env/lib/python3.10/site-packages/django/db/models/sql/query.py", line 1532, in add_q
    clause, _ = self._add_q(q_object, self.used_aliases)
  File "/home/wz/anaconda3/envs/coadd_env/lib/python3.10/site-packages/django/db/models/sql/query.py", line 1562, in _add_q
    child_clause, needed_inner = self.build_filter(
  File "/home/wz/anaconda3/envs/coadd_env/lib/python3.10/site-packages/django/db/models/sql/query.py", line 1407, in build_filter
    lookups, parts, reffed_expression = self.solve_lookup_type(arg)
  File "/home/wz/anaconda3/envs/coadd_env/lib/python3.10/site-packages/django/db/models/sql/query.py", line 1217, in solve_lookup_type
    _, field, _, lookup_parts = self.names_to_path(lookup_splitted, self.get_meta())
  File "/home/wz/anaconda3/envs/coadd_env/lib/python3.10/site-packages/django/db/models/sql/query.py", line 1709, in names_to_path
    raise FieldError(
django.core.exceptions.FieldError: Cannot resolve keyword 'Permission' into field. Choices are: applicationlog, date_joined, department, dictionary_acreated_by, dictionary_adeleted_by, dictionary_aupdated_by, drug_acreated_by, drug_adeleted_by, drug_aupdated_by, email, first_name, group, groups, initials, is_active, is_appuser, is_staff, is_superuser, last_login, last_name, logentry, name, organisation, organism_Biologist, organism_acreated_by, organism_adeleted_by, organism_aupdated_by, organism_batch_Biologist, organism_batch_acreated_by, organism_batch_adeleted_by, organism_batch_aupdated_by, organism_culture_Biologist, organism_culture_acreated_by, organism_culture_adeleted_by, organism_culture_aupdated_by, orgbatch_stock_Biologist, orgbatch_stock_acreated_by, orgbatch_stock_adeleted_by, orgbatch_stock_aupdated_by, password, permission, phone, taxonomy_acreated_by, taxonomy_adeleted_by, taxonomy_aupdated_by, user_permissions, username, vitek_ast_acreated_by, vitek_ast_adeleted_by, vitek_ast_aupdated_by, vitek_card_acreated_by, vitek_card_adeleted_by, vitek_card_aupdated_by, vitek_id_acreated_by, vitek_id_adeleted_by, vitek_id_aupdated_by
"GET /user_list/?paginate_by=50&order_by=&first_name=&last_name=&permission=&Permission=Read HTTP/1.1" 500 160452
Internal Server Error: /user_list/
Traceback (most recent call last):
  File "/home/wz/anaconda3/envs/coadd_env/lib/python3.10/site-packages/django/core/handlers/exception.py", line 55, in inner
    response = get_response(request)
  File "/home/wz/anaconda3/envs/coadd_env/lib/python3.10/site-packages/django/core/handlers/base.py", line 197, in _get_response
    response = wrapped_callback(request, *callback_args, **callback_kwargs)
  File "/home/wz/anaconda3/envs/coadd_env/lib/python3.10/site-packages/django/views/generic/base.py", line 103, in view
    return self.dispatch(request, *args, **kwargs)
  File "/home/wz/anaconda3/envs/coadd_env/lib/python3.10/site-packages/django/contrib/auth/mixins.py", line 73, in dispatch
    return super().dispatch(request, *args, **kwargs)
  File "/home/wz/anaconda3/envs/coadd_env/lib/python3.10/site-packages/django/views/generic/base.py", line 142, in dispatch
    return handler(request, *args, **kwargs)
  File "/home/wz/anaconda3/envs/coadd_env/lib/python3.10/site-packages/django/views/generic/list.py", line 154, in get
    self.object_list = self.get_queryset()
  File "/home/wz/adjCOADD/apputil/utils.py", line 217, in get_queryset
    return self.filterset.qs.distinct().order_by(order)
  File "/home/wz/anaconda3/envs/coadd_env/lib/python3.10/site-packages/django_filters/filterset.py", line 229, in qs
    self.errors
  File "/home/wz/anaconda3/envs/coadd_env/lib/python3.10/site-packages/django_filters/filterset.py", line 202, in errors
    return self.form.errors
  File "/home/wz/anaconda3/envs/coadd_env/lib/python3.10/site-packages/django_filters/filterset.py", line 250, in form
    Form = self.get_form_class()
  File "/home/wz/anaconda3/envs/coadd_env/lib/python3.10/site-packages/django_filters/filterset.py", line 242, in get_form_class
    [(name, filter_.field) for name, filter_ in self.filters.items()]
  File "/home/wz/anaconda3/envs/coadd_env/lib/python3.10/site-packages/django_filters/filterset.py", line 242, in <listcomp>
    [(name, filter_.field) for name, filter_ in self.filters.items()]
  File "/home/wz/anaconda3/envs/coadd_env/lib/python3.10/site-packages/django_filters/filters.py", line 149, in field
    self._field = self.field_class(label=self.label, **field_kwargs)
  File "/home/wz/anaconda3/envs/coadd_env/lib/python3.10/site-packages/django_filters/fields.py", line 278, in __init__
    super().__init__(*args, **kwargs)
  File "/home/wz/anaconda3/envs/coadd_env/lib/python3.10/site-packages/django_filters/fields.py", line 258, in __init__
    super().__init__(*args, **kwargs)
  File "/home/wz/anaconda3/envs/coadd_env/lib/python3.10/site-packages/django/forms/fields.py", line 861, in __init__
    super().__init__(**kwargs)
TypeError: Field.__init__() got an unexpected keyword argument 'blank'
"GET /user_list/?paginate_by=50&order_by=-Initial&first_name=&last_name=&permission=Read HTTP/1.1" 500 130200
Internal Server Error: /user_list/
Traceback (most recent call last):
  File "/home/wz/anaconda3/envs/coadd_env/lib/python3.10/site-packages/django/core/handlers/exception.py", line 55, in inner
    response = get_response(request)
  File "/home/wz/anaconda3/envs/coadd_env/lib/python3.10/site-packages/django/core/handlers/base.py", line 197, in _get_response
    response = wrapped_callback(request, *callback_args, **callback_kwargs)
  File "/home/wz/anaconda3/envs/coadd_env/lib/python3.10/site-packages/django/views/generic/base.py", line 103, in view
    return self.dispatch(request, *args, **kwargs)
  File "/home/wz/anaconda3/envs/coadd_env/lib/python3.10/site-packages/django/contrib/auth/mixins.py", line 73, in dispatch
    return super().dispatch(request, *args, **kwargs)
  File "/home/wz/anaconda3/envs/coadd_env/lib/python3.10/site-packages/django/views/generic/base.py", line 142, in dispatch
    return handler(request, *args, **kwargs)
  File "/home/wz/anaconda3/envs/coadd_env/lib/python3.10/site-packages/django/views/generic/list.py", line 154, in get
    self.object_list = self.get_queryset()
  File "/home/wz/adjCOADD/apputil/utils.py", line 217, in get_queryset
    return self.filterset.qs.distinct().order_by(order)
  File "/home/wz/anaconda3/envs/coadd_env/lib/python3.10/site-packages/django_filters/filterset.py", line 229, in qs
    self.errors
  File "/home/wz/anaconda3/envs/coadd_env/lib/python3.10/site-packages/django_filters/filterset.py", line 202, in errors
    return self.form.errors
  File "/home/wz/anaconda3/envs/coadd_env/lib/python3.10/site-packages/django_filters/filterset.py", line 250, in form
    Form = self.get_form_class()
  File "/home/wz/anaconda3/envs/coadd_env/lib/python3.10/site-packages/django_filters/filterset.py", line 242, in get_form_class
    [(name, filter_.field) for name, filter_ in self.filters.items()]
  File "/home/wz/anaconda3/envs/coadd_env/lib/python3.10/site-packages/django_filters/filterset.py", line 242, in <listcomp>
    [(name, filter_.field) for name, filter_ in self.filters.items()]
  File "/home/wz/anaconda3/envs/coadd_env/lib/python3.10/site-packages/django_filters/filters.py", line 149, in field
    self._field = self.field_class(label=self.label, **field_kwargs)
  File "/home/wz/anaconda3/envs/coadd_env/lib/python3.10/site-packages/django_filters/fields.py", line 278, in __init__
    super().__init__(*args, **kwargs)
  File "/home/wz/anaconda3/envs/coadd_env/lib/python3.10/site-packages/django_filters/fields.py", line 258, in __init__
    super().__init__(*args, **kwargs)
  File "/home/wz/anaconda3/envs/coadd_env/lib/python3.10/site-packages/django/forms/fields.py", line 861, in __init__
    super().__init__(**kwargs)
TypeError: Field.__init__() got an unexpected keyword argument 'blank'
"GET /user_list/?paginate_by=50&order_by=-Initial&first_name=&last_name=&permission=Read HTTP/1.1" 500 130379
