Not Found: /userslist
Not Found: /user_list
Not Found: /user_list
Internal Server Error: /user_update/Test1676265711.4118989
Traceback (most recent call last):
  File "/home/wz/anaconda3/envs/coadd_env/lib/python3.10/site-packages/django/core/handlers/exception.py", line 55, in inner
    response = get_response(request)
  File "/home/wz/anaconda3/envs/coadd_env/lib/python3.10/site-packages/django/core/handlers/base.py", line 197, in _get_response
    response = wrapped_callback(request, *callback_args, **callback_kwargs)
  File "/home/wz/anaconda3/envs/coadd_env/lib/python3.10/site-packages/django/contrib/auth/decorators.py", line 22, in _wrapped_view
    if test_func(request.user):
  File "/home/wz/adjCOADD/apputil/views.py", line 82, in <lambda>
    @user_passes_test(lambda u: u.has_permission('Admin'), login_url='permission_not_granted')
  File "/home/wz/anaconda3/envs/coadd_env/lib/python3.10/site-packages/django/utils/functional.py", line 268, in inner
    return func(_wrapped, *args)
AttributeError: 'AnonymousUser' object has no attribute 'has_permission'
Internal Server Error: /user_update/Test1676265747.6970694
Traceback (most recent call last):
  File "/home/wz/anaconda3/envs/coadd_env/lib/python3.10/site-packages/django/core/handlers/exception.py", line 55, in inner
    response = get_response(request)
  File "/home/wz/anaconda3/envs/coadd_env/lib/python3.10/site-packages/django/core/handlers/base.py", line 197, in _get_response
    response = wrapped_callback(request, *callback_args, **callback_kwargs)
  File "/home/wz/anaconda3/envs/coadd_env/lib/python3.10/site-packages/django/contrib/auth/decorators.py", line 22, in _wrapped_view
    if test_func(request.user):
  File "/home/wz/adjCOADD/apputil/views.py", line 82, in <lambda>
    @user_passes_test(lambda u: u.has_permission('Admin'), login_url='permission_not_granted')
  File "/home/wz/anaconda3/envs/coadd_env/lib/python3.10/site-packages/django/utils/functional.py", line 268, in inner
    return func(_wrapped, *args)
AttributeError: 'AnonymousUser' object has no attribute 'has_permission'
Internal Server Error: /user_update/somename
Traceback (most recent call last):
  File "/home/wz/anaconda3/envs/coadd_env/lib/python3.10/site-packages/django/core/handlers/exception.py", line 55, in inner
    response = get_response(request)
  File "/home/wz/anaconda3/envs/coadd_env/lib/python3.10/site-packages/django/core/handlers/base.py", line 197, in _get_response
    response = wrapped_callback(request, *callback_args, **callback_kwargs)
  File "/home/wz/anaconda3/envs/coadd_env/lib/python3.10/site-packages/django/contrib/auth/decorators.py", line 22, in _wrapped_view
    if test_func(request.user):
  File "/home/wz/adjCOADD/apputil/views.py", line 82, in <lambda>
    @user_passes_test(lambda u: u.has_permission('Admin'), login_url='permission_not_granted')
  File "/home/wz/anaconda3/envs/coadd_env/lib/python3.10/site-packages/django/utils/functional.py", line 268, in inner
    return func(_wrapped, *args)
AttributeError: 'AnonymousUser' object has no attribute 'has_permission'
Internal Server Error: /user_update/test
Traceback (most recent call last):
  File "/home/wz/anaconda3/envs/coadd_env/lib/python3.10/site-packages/django/core/handlers/exception.py", line 55, in inner
    response = get_response(request)
  File "/home/wz/anaconda3/envs/coadd_env/lib/python3.10/site-packages/django/core/handlers/base.py", line 197, in _get_response
    response = wrapped_callback(request, *callback_args, **callback_kwargs)
  File "/home/wz/anaconda3/envs/coadd_env/lib/python3.10/site-packages/django/contrib/auth/decorators.py", line 22, in _wrapped_view
    if test_func(request.user):
  File "/home/wz/adjCOADD/apputil/views.py", line 82, in <lambda>
    @user_passes_test(lambda u: u.has_permission('Admin'), login_url='permission_not_granted')
  File "/home/wz/anaconda3/envs/coadd_env/lib/python3.10/site-packages/django/utils/functional.py", line 268, in inner
    return func(_wrapped, *args)
AttributeError: 'AnonymousUser' object has no attribute 'has_permission'
Internal Server Error: /user_update/test
Traceback (most recent call last):
  File "/home/wz/anaconda3/envs/coadd_env/lib/python3.10/site-packages/django/core/handlers/exception.py", line 55, in inner
    response = get_response(request)
  File "/home/wz/anaconda3/envs/coadd_env/lib/python3.10/site-packages/django/core/handlers/base.py", line 197, in _get_response
    response = wrapped_callback(request, *callback_args, **callback_kwargs)
  File "/home/wz/anaconda3/envs/coadd_env/lib/python3.10/site-packages/django/contrib/auth/decorators.py", line 22, in _wrapped_view
    if test_func(request.user):
  File "/home/wz/adjCOADD/apputil/views.py", line 82, in <lambda>
    @user_passes_test(lambda u: u.has_permission('Admin'), login_url='permission_not_granted')
  File "/home/wz/anaconda3/envs/coadd_env/lib/python3.10/site-packages/django/utils/functional.py", line 268, in inner
    return func(_wrapped, *args)
AttributeError: 'AnonymousUser' object has no attribute 'has_permission'
