
Forbidden (Permission denied): /user_delete/django
Traceback (most recent call last):
  File "/home/wz/anaconda3/envs/coadd_env/lib/python3.10/site-packages/django/core/handlers/exception.py", line 55, in inner
    response = get_response(request)
  File "/home/wz/anaconda3/envs/coadd_env/lib/python3.10/site-packages/django/core/handlers/base.py", line 197, in _get_response
    response = wrapped_callback(request, *callback_args, **callback_kwargs)
  File "/home/wz/anaconda3/envs/coadd_env/lib/python3.10/site-packages/django/views/generic/base.py", line 103, in view
    return self.dispatch(request, *args, **kwargs)
  File "/home/wz/anaconda3/envs/coadd_env/lib/python3.10/site-packages/django/contrib/auth/mixins.py", line 73, in dispatch
    return super().dispatch(request, *args, **kwargs)
  File "/home/wz/anaconda3/envs/coadd_env/lib/python3.10/site-packages/django/contrib/auth/mixins.py", line 134, in dispatch
    return self.handle_no_permission()
  File "/home/wz/anaconda3/envs/coadd_env/lib/python3.10/site-packages/django/contrib/auth/mixins.py", line 48, in handle_no_permission
    raise PermissionDenied(self.get_permission_denied_message())
django.core.exceptions.PermissionDenied
"POST /user_delete/django HTTP/1.1" 403 135
Not Found: /favicon.ico
"GET /favicon.ico HTTP/1.1" 404 11284
Forbidden (CSRF token from POST incorrect.): /accounts/login/
"POST /accounts/login/ HTTP/1.1" 403 2518
Not Found: /favicon.ico
"GET /favicon.ico HTTP/1.1" 404 11284
Forbidden (CSRF token from POST incorrect.): /accounts/login/
"POST /accounts/login/ HTTP/1.1" 403 2518
Not Found: /favicon.ico
"GET /favicon.ico HTTP/1.1" 404 11284
Not Found: /favicon.ico
"GET /favicon.ico HTTP/1.1" 404 11284
Internal Server Error: /vitekcard_list
Traceback (most recent call last):
  File "C:\Users\uqwzhon4\Anaconda3\envs\orgdb_env\Lib\site-packages\django\core\handlers\exception.py", line 55, in inner
    response = get_response(request)
               ^^^^^^^^^^^^^^^^^^^^^
  File "C:\Users\uqwzhon4\Anaconda3\envs\orgdb_env\Lib\site-packages\django\utils\deprecation.py", line 138, in __call__
    response = self.process_response(request, response)
               ^^^^^^^^^^^^^^^^^^^^^^^^^^^^^^^^^^^^^^^^
  File "C:\Users\uqwzhon4\Anaconda3\envs\orgdb_env\Lib\site-packages\django\middleware\clickjacking.py", line 27, in process_response
    if response.get("X-Frame-Options") is not None:
       ^^^^^^^^^^^^
AttributeError: 'str' object has no attribute 'get'
"POST /vitekcard_list HTTP/1.1" 500 80150
Internal Server Error: /vitekcard_list
Traceback (most recent call last):
  File "C:\Users\uqwzhon4\Anaconda3\envs\orgdb_env\Lib\site-packages\django\core\handlers\exception.py", line 55, in inner
    response = get_response(request)
               ^^^^^^^^^^^^^^^^^^^^^
  File "C:\Users\uqwzhon4\Anaconda3\envs\orgdb_env\Lib\site-packages\django\core\handlers\base.py", line 197, in _get_response
    response = wrapped_callback(request, *callback_args, **callback_kwargs)
               ^^^^^^^^^^^^^^^^^^^^^^^^^^^^^^^^^^^^^^^^^^^^^^^^^^^^^^^^^^^^
  File "C:\Users\uqwzhon4\Anaconda3\envs\orgdb_env\Lib\site-packages\django\views\generic\base.py", line 103, in view
    return self.dispatch(request, *args, **kwargs)
           ^^^^^^^^^^^^^^^^^^^^^^^^^^^^^^^^^^^^^^^
  File "C:\Users\uqwzhon4\Anaconda3\envs\orgdb_env\Lib\site-packages\django\contrib\auth\mixins.py", line 73, in dispatch
    return super().dispatch(request, *args, **kwargs)
           ^^^^^^^^^^^^^^^^^^^^^^^^^^^^^^^^^^^^^^^^^^
  File "C:\Users\uqwzhon4\Anaconda3\envs\orgdb_env\Lib\site-packages\django\views\generic\base.py", line 142, in dispatch
    return handler(request, *args, **kwargs)
           ^^^^^^^^^^^^^^^^^^^^^^^^^^^^^^^^^
  File "C:\Users\uqwzhon4\Project\adjCOADD\ddrug\views.py", line 148, in post
    aggfunc=np_aggfunc[request.POST.get("functions")]
            ^^^^^^^^^^
NameError: name 'np_aggfunc' is not defined
"POST /vitekcard_list HTTP/1.1" 500 88660
Internal Server Error: /vitekcard_list
Traceback (most recent call last):
  File "C:\Users\uqwzhon4\Anaconda3\envs\orgdb_env\Lib\site-packages\django\core\handlers\exception.py", line 55, in inner
    response = get_response(request)
               ^^^^^^^^^^^^^^^^^^^^^
  File "C:\Users\uqwzhon4\Anaconda3\envs\orgdb_env\Lib\site-packages\django\core\handlers\base.py", line 197, in _get_response
    response = wrapped_callback(request, *callback_args, **callback_kwargs)
               ^^^^^^^^^^^^^^^^^^^^^^^^^^^^^^^^^^^^^^^^^^^^^^^^^^^^^^^^^^^^
  File "C:\Users\uqwzhon4\Anaconda3\envs\orgdb_env\Lib\site-packages\django\views\generic\base.py", line 103, in view
    return self.dispatch(request, *args, **kwargs)
           ^^^^^^^^^^^^^^^^^^^^^^^^^^^^^^^^^^^^^^^
  File "C:\Users\uqwzhon4\Anaconda3\envs\orgdb_env\Lib\site-packages\django\contrib\auth\mixins.py", line 73, in dispatch
    return super().dispatch(request, *args, **kwargs)
           ^^^^^^^^^^^^^^^^^^^^^^^^^^^^^^^^^^^^^^^^^^
  File "C:\Users\uqwzhon4\Anaconda3\envs\orgdb_env\Lib\site-packages\django\views\generic\base.py", line 142, in dispatch
    return handler(request, *args, **kwargs)
           ^^^^^^^^^^^^^^^^^^^^^^^^^^^^^^^^^
  File "C:\Users\uqwzhon4\Project\adjCOADD\ddrug\views.py", line 148, in post
    aggfunc=np_aggfunc[request.POST.get("functions")]
            ^^^^^^^^^^
NameError: name 'np_aggfunc' is not defined
"POST /vitekcard_list HTTP/1.1" 500 88660
Internal Server Error: /vitekcard_list
Traceback (most recent call last):
  File "C:\Users\uqwzhon4\Anaconda3\envs\orgdb_env\Lib\site-packages\django\core\handlers\exception.py", line 55, in inner
    response = get_response(request)
               ^^^^^^^^^^^^^^^^^^^^^
  File "C:\Users\uqwzhon4\Anaconda3\envs\orgdb_env\Lib\site-packages\django\core\handlers\base.py", line 197, in _get_response
    response = wrapped_callback(request, *callback_args, **callback_kwargs)
               ^^^^^^^^^^^^^^^^^^^^^^^^^^^^^^^^^^^^^^^^^^^^^^^^^^^^^^^^^^^^
  File "C:\Users\uqwzhon4\Anaconda3\envs\orgdb_env\Lib\site-packages\django\views\generic\base.py", line 103, in view
    return self.dispatch(request, *args, **kwargs)
           ^^^^^^^^^^^^^^^^^^^^^^^^^^^^^^^^^^^^^^^
  File "C:\Users\uqwzhon4\Anaconda3\envs\orgdb_env\Lib\site-packages\django\contrib\auth\mixins.py", line 73, in dispatch
    return super().dispatch(request, *args, **kwargs)
           ^^^^^^^^^^^^^^^^^^^^^^^^^^^^^^^^^^^^^^^^^^
  File "C:\Users\uqwzhon4\Anaconda3\envs\orgdb_env\Lib\site-packages\django\views\generic\base.py", line 142, in dispatch
    return handler(request, *args, **kwargs)
           ^^^^^^^^^^^^^^^^^^^^^^^^^^^^^^^^^
  File "C:\Users\uqwzhon4\Project\adjCOADD\ddrug\views.py", line 148, in post
    aggfunc=np_aggfunc[request.POST.get("functions")]
            ^^^^^^^^^^
NameError: name 'np_aggfunc' is not defined
"POST /vitekcard_list HTTP/1.1" 500 88660
Internal Server Error: /vitekcard_list
Traceback (most recent call last):
  File "C:\Users\uqwzhon4\Anaconda3\envs\orgdb_env\Lib\site-packages\django\core\handlers\exception.py", line 55, in inner
    response = get_response(request)
               ^^^^^^^^^^^^^^^^^^^^^
  File "C:\Users\uqwzhon4\Anaconda3\envs\orgdb_env\Lib\site-packages\django\core\handlers\base.py", line 197, in _get_response
    response = wrapped_callback(request, *callback_args, **callback_kwargs)
               ^^^^^^^^^^^^^^^^^^^^^^^^^^^^^^^^^^^^^^^^^^^^^^^^^^^^^^^^^^^^
  File "C:\Users\uqwzhon4\Anaconda3\envs\orgdb_env\Lib\site-packages\django\views\generic\base.py", line 103, in view
    return self.dispatch(request, *args, **kwargs)
           ^^^^^^^^^^^^^^^^^^^^^^^^^^^^^^^^^^^^^^^
  File "C:\Users\uqwzhon4\Anaconda3\envs\orgdb_env\Lib\site-packages\django\contrib\auth\mixins.py", line 73, in dispatch
    return super().dispatch(request, *args, **kwargs)
           ^^^^^^^^^^^^^^^^^^^^^^^^^^^^^^^^^^^^^^^^^^
  File "C:\Users\uqwzhon4\Anaconda3\envs\orgdb_env\Lib\site-packages\django\views\generic\base.py", line 142, in dispatch
    return handler(request, *args, **kwargs)
           ^^^^^^^^^^^^^^^^^^^^^^^^^^^^^^^^^
  File "C:\Users\uqwzhon4\Project\adjCOADD\ddrug\views.py", line 148, in post
    aggfunc=np_aggfunc[request.POST.get("functions")]
            ^^^^^^^^^^
NameError: name 'np_aggfunc' is not defined
"POST /vitekcard_list HTTP/1.1" 500 88660
Internal Server Error: /vitekcard_list
Traceback (most recent call last):
  File "C:\Users\uqwzhon4\Anaconda3\envs\orgdb_env\Lib\site-packages\django\core\handlers\exception.py", line 55, in inner
    response = get_response(request)
               ^^^^^^^^^^^^^^^^^^^^^
  File "C:\Users\uqwzhon4\Anaconda3\envs\orgdb_env\Lib\site-packages\django\core\handlers\base.py", line 197, in _get_response
    response = wrapped_callback(request, *callback_args, **callback_kwargs)
               ^^^^^^^^^^^^^^^^^^^^^^^^^^^^^^^^^^^^^^^^^^^^^^^^^^^^^^^^^^^^
  File "C:\Users\uqwzhon4\Anaconda3\envs\orgdb_env\Lib\site-packages\django\views\generic\base.py", line 103, in view
    return self.dispatch(request, *args, **kwargs)
           ^^^^^^^^^^^^^^^^^^^^^^^^^^^^^^^^^^^^^^^
  File "C:\Users\uqwzhon4\Anaconda3\envs\orgdb_env\Lib\site-packages\django\contrib\auth\mixins.py", line 73, in dispatch
    return super().dispatch(request, *args, **kwargs)
           ^^^^^^^^^^^^^^^^^^^^^^^^^^^^^^^^^^^^^^^^^^
  File "C:\Users\uqwzhon4\Anaconda3\envs\orgdb_env\Lib\site-packages\django\views\generic\base.py", line 142, in dispatch
    return handler(request, *args, **kwargs)
           ^^^^^^^^^^^^^^^^^^^^^^^^^^^^^^^^^
  File "C:\Users\uqwzhon4\Project\adjCOADD\ddrug\views.py", line 148, in post
    aggfunc=np_aggfunc[request.POST.get("functions")]
            ^^^^^^^^^^
NameError: name 'np_aggfunc' is not defined
"POST /vitekcard_list HTTP/1.1" 500 88660
Internal Server Error: /vitekcard_list
Traceback (most recent call last):
  File "C:\Users\uqwzhon4\Anaconda3\envs\orgdb_env\Lib\site-packages\django\core\handlers\exception.py", line 55, in inner
    response = get_response(request)
               ^^^^^^^^^^^^^^^^^^^^^
  File "C:\Users\uqwzhon4\Anaconda3\envs\orgdb_env\Lib\site-packages\django\core\handlers\base.py", line 197, in _get_response
    response = wrapped_callback(request, *callback_args, **callback_kwargs)
               ^^^^^^^^^^^^^^^^^^^^^^^^^^^^^^^^^^^^^^^^^^^^^^^^^^^^^^^^^^^^
  File "C:\Users\uqwzhon4\Anaconda3\envs\orgdb_env\Lib\site-packages\django\views\generic\base.py", line 103, in view
    return self.dispatch(request, *args, **kwargs)
           ^^^^^^^^^^^^^^^^^^^^^^^^^^^^^^^^^^^^^^^
  File "C:\Users\uqwzhon4\Anaconda3\envs\orgdb_env\Lib\site-packages\django\contrib\auth\mixins.py", line 73, in dispatch
    return super().dispatch(request, *args, **kwargs)
           ^^^^^^^^^^^^^^^^^^^^^^^^^^^^^^^^^^^^^^^^^^
  File "C:\Users\uqwzhon4\Anaconda3\envs\orgdb_env\Lib\site-packages\django\views\generic\base.py", line 142, in dispatch
    return handler(request, *args, **kwargs)
           ^^^^^^^^^^^^^^^^^^^^^^^^^^^^^^^^^
  File "C:\Users\uqwzhon4\Project\adjCOADD\ddrug\views.py", line 148, in post
    aggfunc=np_aggfunc[request.POST.get("functions")]
            ^^^^^^^^^^
NameError: name 'np_aggfunc' is not defined
"POST /vitekcard_list HTTP/1.1" 500 90357
Internal Server Error: /vitekcard_list
Traceback (most recent call last):
  File "C:\Users\uqwzhon4\Anaconda3\envs\orgdb_env\Lib\site-packages\django\contrib\sessions\backends\base.py", line 187, in _get_session
    return self._session_cache
           ^^^^^^^^^^^^^^^^^^^
AttributeError: 'SessionStore' object has no attribute '_session_cache'

During handling of the above exception, another exception occurred:

Traceback (most recent call last):
  File "C:\Users\uqwzhon4\Anaconda3\envs\orgdb_env\Lib\site-packages\django\core\handlers\exception.py", line 55, in inner
    response = get_response(request)
               ^^^^^^^^^^^^^^^^^^^^^
  File "C:\Users\uqwzhon4\Anaconda3\envs\orgdb_env\Lib\site-packages\django\core\handlers\base.py", line 197, in _get_response
    response = wrapped_callback(request, *callback_args, **callback_kwargs)
               ^^^^^^^^^^^^^^^^^^^^^^^^^^^^^^^^^^^^^^^^^^^^^^^^^^^^^^^^^^^^
  File "C:\Users\uqwzhon4\Anaconda3\envs\orgdb_env\Lib\site-packages\asgiref\sync.py", line 240, in __call__
    return call_result.result()
           ^^^^^^^^^^^^^^^^^^^^
  File "C:\Users\uqwzhon4\Anaconda3\envs\orgdb_env\Lib\concurrent\futures\_base.py", line 449, in result
    return self.__get_result()
           ^^^^^^^^^^^^^^^^^^^
  File "C:\Users\uqwzhon4\Anaconda3\envs\orgdb_env\Lib\concurrent\futures\_base.py", line 401, in __get_result
    raise self._exception
  File "C:\Users\uqwzhon4\Anaconda3\envs\orgdb_env\Lib\site-packages\asgiref\sync.py", line 306, in main_wrap
    result = await self.awaitable(*args, **kwargs)
                   ^^^^^^^^^^^^^^^^^^^^^^^^^^^^^^^
  File "C:\Users\uqwzhon4\Anaconda3\envs\orgdb_env\Lib\site-packages\django\views\generic\base.py", line 103, in view
    return self.dispatch(request, *args, **kwargs)
           ^^^^^^^^^^^^^^^^^^^^^^^^^^^^^^^^^^^^^^^
  File "C:\Users\uqwzhon4\Anaconda3\envs\orgdb_env\Lib\site-packages\django\contrib\auth\mixins.py", line 71, in dispatch
    if not request.user.is_authenticated:
           ^^^^^^^^^^^^^^^^^^^^^^^^^^^^^
  File "C:\Users\uqwzhon4\Anaconda3\envs\orgdb_env\Lib\site-packages\django\utils\functional.py", line 266, in inner
    self._setup()
  File "C:\Users\uqwzhon4\Anaconda3\envs\orgdb_env\Lib\site-packages\django\utils\functional.py", line 419, in _setup
    self._wrapped = self._setupfunc()
                    ^^^^^^^^^^^^^^^^^
  File "C:\Users\uqwzhon4\Anaconda3\envs\orgdb_env\Lib\site-packages\django\contrib\auth\middleware.py", line 25, in <lambda>
    request.user = SimpleLazyObject(lambda: get_user(request))
                                            ^^^^^^^^^^^^^^^^^
  File "C:\Users\uqwzhon4\Anaconda3\envs\orgdb_env\Lib\site-packages\django\contrib\auth\middleware.py", line 11, in get_user
    request._cached_user = auth.get_user(request)
                           ^^^^^^^^^^^^^^^^^^^^^^
  File "C:\Users\uqwzhon4\Anaconda3\envs\orgdb_env\Lib\site-packages\django\contrib\auth\__init__.py", line 191, in get_user
    user_id = _get_user_session_key(request)
              ^^^^^^^^^^^^^^^^^^^^^^^^^^^^^^
  File "C:\Users\uqwzhon4\Anaconda3\envs\orgdb_env\Lib\site-packages\django\contrib\auth\__init__.py", line 60, in _get_user_session_key
    return get_user_model()._meta.pk.to_python(request.session[SESSION_KEY])
                                               ~~~~~~~~~~~~~~~^^^^^^^^^^^^^
  File "C:\Users\uqwzhon4\Anaconda3\envs\orgdb_env\Lib\site-packages\django\contrib\sessions\backends\base.py", line 53, in __getitem__
    return self._session[key]
           ^^^^^^^^^^^^^
  File "C:\Users\uqwzhon4\Anaconda3\envs\orgdb_env\Lib\site-packages\django\contrib\sessions\backends\base.py", line 192, in _get_session
    self._session_cache = self.load()
                          ^^^^^^^^^^^
  File "C:\Users\uqwzhon4\Anaconda3\envs\orgdb_env\Lib\site-packages\django\contrib\sessions\backends\db.py", line 42, in load
    s = self._get_session_from_db()
        ^^^^^^^^^^^^^^^^^^^^^^^^^^^
  File "C:\Users\uqwzhon4\Anaconda3\envs\orgdb_env\Lib\site-packages\django\contrib\sessions\backends\db.py", line 32, in _get_session_from_db
    return self.model.objects.get(
           ^^^^^^^^^^^^^^^^^^^^^^^
  File "C:\Users\uqwzhon4\Anaconda3\envs\orgdb_env\Lib\site-packages\django\db\models\manager.py", line 85, in manager_method
    return getattr(self.get_queryset(), name)(*args, **kwargs)
           ^^^^^^^^^^^^^^^^^^^^^^^^^^^^^^^^^^^^^^^^^^^^^^^^^^^
  File "C:\Users\uqwzhon4\Anaconda3\envs\orgdb_env\Lib\site-packages\django\db\models\query.py", line 646, in get
    num = len(clone)
          ^^^^^^^^^^
  File "C:\Users\uqwzhon4\Anaconda3\envs\orgdb_env\Lib\site-packages\django\db\models\query.py", line 376, in __len__
    self._fetch_all()
  File "C:\Users\uqwzhon4\Anaconda3\envs\orgdb_env\Lib\site-packages\django\db\models\query.py", line 1867, in _fetch_all
    self._result_cache = list(self._iterable_class(self))
                         ^^^^^^^^^^^^^^^^^^^^^^^^^^^^^^^^
  File "C:\Users\uqwzhon4\Anaconda3\envs\orgdb_env\Lib\site-packages\django\db\models\query.py", line 87, in __iter__
    results = compiler.execute_sql(
              ^^^^^^^^^^^^^^^^^^^^^
  File "C:\Users\uqwzhon4\Anaconda3\envs\orgdb_env\Lib\site-packages\django\db\models\sql\compiler.py", line 1396, in execute_sql
    cursor = self.connection.cursor()
             ^^^^^^^^^^^^^^^^^^^^^^^^
  File "C:\Users\uqwzhon4\Anaconda3\envs\orgdb_env\Lib\site-packages\django\utils\asyncio.py", line 24, in inner
    raise SynchronousOnlyOperation(message)
django.core.exceptions.SynchronousOnlyOperation: You cannot call this from an async context - use a thread or sync_to_async.
"GET /vitekcard_list HTTP/1.1" 500 167759
Not Found: /favicon.ico
"GET /favicon.ico HTTP/1.1" 404 11284
Internal Server Error: /vitekcard_list
Traceback (most recent call last):
  File "C:\Users\uqwzhon4\Anaconda3\envs\orgdb_env\Lib\site-packages\django\contrib\sessions\backends\base.py", line 187, in _get_session
    return self._session_cache
           ^^^^^^^^^^^^^^^^^^^
AttributeError: 'SessionStore' object has no attribute '_session_cache'

During handling of the above exception, another exception occurred:

Traceback (most recent call last):
  File "C:\Users\uqwzhon4\Anaconda3\envs\orgdb_env\Lib\site-packages\django\core\handlers\exception.py", line 55, in inner
    response = get_response(request)
               ^^^^^^^^^^^^^^^^^^^^^
  File "C:\Users\uqwzhon4\Anaconda3\envs\orgdb_env\Lib\site-packages\django\core\handlers\base.py", line 197, in _get_response
    response = wrapped_callback(request, *callback_args, **callback_kwargs)
               ^^^^^^^^^^^^^^^^^^^^^^^^^^^^^^^^^^^^^^^^^^^^^^^^^^^^^^^^^^^^
  File "C:\Users\uqwzhon4\Anaconda3\envs\orgdb_env\Lib\site-packages\asgiref\sync.py", line 240, in __call__
    return call_result.result()
           ^^^^^^^^^^^^^^^^^^^^
  File "C:\Users\uqwzhon4\Anaconda3\envs\orgdb_env\Lib\concurrent\futures\_base.py", line 449, in result
    return self.__get_result()
           ^^^^^^^^^^^^^^^^^^^
  File "C:\Users\uqwzhon4\Anaconda3\envs\orgdb_env\Lib\concurrent\futures\_base.py", line 401, in __get_result
    raise self._exception
  File "C:\Users\uqwzhon4\Anaconda3\envs\orgdb_env\Lib\site-packages\asgiref\sync.py", line 306, in main_wrap
    result = await self.awaitable(*args, **kwargs)
                   ^^^^^^^^^^^^^^^^^^^^^^^^^^^^^^^
  File "C:\Users\uqwzhon4\Anaconda3\envs\orgdb_env\Lib\site-packages\django\views\generic\base.py", line 103, in view
    return self.dispatch(request, *args, **kwargs)
           ^^^^^^^^^^^^^^^^^^^^^^^^^^^^^^^^^^^^^^^
  File "C:\Users\uqwzhon4\Anaconda3\envs\orgdb_env\Lib\site-packages\django\contrib\auth\mixins.py", line 71, in dispatch
    if not request.user.is_authenticated:
           ^^^^^^^^^^^^^^^^^^^^^^^^^^^^^
  File "C:\Users\uqwzhon4\Anaconda3\envs\orgdb_env\Lib\site-packages\django\utils\functional.py", line 266, in inner
    self._setup()
  File "C:\Users\uqwzhon4\Anaconda3\envs\orgdb_env\Lib\site-packages\django\utils\functional.py", line 419, in _setup
    self._wrapped = self._setupfunc()
                    ^^^^^^^^^^^^^^^^^
  File "C:\Users\uqwzhon4\Anaconda3\envs\orgdb_env\Lib\site-packages\django\contrib\auth\middleware.py", line 25, in <lambda>
    request.user = SimpleLazyObject(lambda: get_user(request))
                                            ^^^^^^^^^^^^^^^^^
  File "C:\Users\uqwzhon4\Anaconda3\envs\orgdb_env\Lib\site-packages\django\contrib\auth\middleware.py", line 11, in get_user
    request._cached_user = auth.get_user(request)
                           ^^^^^^^^^^^^^^^^^^^^^^
  File "C:\Users\uqwzhon4\Anaconda3\envs\orgdb_env\Lib\site-packages\django\contrib\auth\__init__.py", line 191, in get_user
    user_id = _get_user_session_key(request)
              ^^^^^^^^^^^^^^^^^^^^^^^^^^^^^^
  File "C:\Users\uqwzhon4\Anaconda3\envs\orgdb_env\Lib\site-packages\django\contrib\auth\__init__.py", line 60, in _get_user_session_key
    return get_user_model()._meta.pk.to_python(request.session[SESSION_KEY])
                                               ~~~~~~~~~~~~~~~^^^^^^^^^^^^^
  File "C:\Users\uqwzhon4\Anaconda3\envs\orgdb_env\Lib\site-packages\django\contrib\sessions\backends\base.py", line 53, in __getitem__
    return self._session[key]
           ^^^^^^^^^^^^^
  File "C:\Users\uqwzhon4\Anaconda3\envs\orgdb_env\Lib\site-packages\django\contrib\sessions\backends\base.py", line 192, in _get_session
    self._session_cache = self.load()
                          ^^^^^^^^^^^
  File "C:\Users\uqwzhon4\Anaconda3\envs\orgdb_env\Lib\site-packages\django\contrib\sessions\backends\db.py", line 42, in load
    s = self._get_session_from_db()
        ^^^^^^^^^^^^^^^^^^^^^^^^^^^
  File "C:\Users\uqwzhon4\Anaconda3\envs\orgdb_env\Lib\site-packages\django\contrib\sessions\backends\db.py", line 32, in _get_session_from_db
    return self.model.objects.get(
           ^^^^^^^^^^^^^^^^^^^^^^^
  File "C:\Users\uqwzhon4\Anaconda3\envs\orgdb_env\Lib\site-packages\django\db\models\manager.py", line 85, in manager_method
    return getattr(self.get_queryset(), name)(*args, **kwargs)
           ^^^^^^^^^^^^^^^^^^^^^^^^^^^^^^^^^^^^^^^^^^^^^^^^^^^
  File "C:\Users\uqwzhon4\Anaconda3\envs\orgdb_env\Lib\site-packages\django\db\models\query.py", line 646, in get
    num = len(clone)
          ^^^^^^^^^^
  File "C:\Users\uqwzhon4\Anaconda3\envs\orgdb_env\Lib\site-packages\django\db\models\query.py", line 376, in __len__
    self._fetch_all()
  File "C:\Users\uqwzhon4\Anaconda3\envs\orgdb_env\Lib\site-packages\django\db\models\query.py", line 1867, in _fetch_all
    self._result_cache = list(self._iterable_class(self))
                         ^^^^^^^^^^^^^^^^^^^^^^^^^^^^^^^^
  File "C:\Users\uqwzhon4\Anaconda3\envs\orgdb_env\Lib\site-packages\django\db\models\query.py", line 87, in __iter__
    results = compiler.execute_sql(
              ^^^^^^^^^^^^^^^^^^^^^
  File "C:\Users\uqwzhon4\Anaconda3\envs\orgdb_env\Lib\site-packages\django\db\models\sql\compiler.py", line 1396, in execute_sql
    cursor = self.connection.cursor()
             ^^^^^^^^^^^^^^^^^^^^^^^^
  File "C:\Users\uqwzhon4\Anaconda3\envs\orgdb_env\Lib\site-packages\django\utils\asyncio.py", line 24, in inner
    raise SynchronousOnlyOperation(message)
django.core.exceptions.SynchronousOnlyOperation: You cannot call this from an async context - use a thread or sync_to_async.
"GET /vitekcard_list HTTP/1.1" 500 167739
Internal Server Error: /vitekcard_list
Traceback (most recent call last):
  File "C:\Users\uqwzhon4\Anaconda3\envs\orgdb_env\Lib\site-packages\django\contrib\sessions\backends\base.py", line 187, in _get_session
    return self._session_cache
           ^^^^^^^^^^^^^^^^^^^
AttributeError: 'SessionStore' object has no attribute '_session_cache'

During handling of the above exception, another exception occurred:

Traceback (most recent call last):
  File "C:\Users\uqwzhon4\Anaconda3\envs\orgdb_env\Lib\site-packages\django\core\handlers\exception.py", line 55, in inner
    response = get_response(request)
               ^^^^^^^^^^^^^^^^^^^^^
  File "C:\Users\uqwzhon4\Anaconda3\envs\orgdb_env\Lib\site-packages\django\core\handlers\base.py", line 197, in _get_response
    response = wrapped_callback(request, *callback_args, **callback_kwargs)
               ^^^^^^^^^^^^^^^^^^^^^^^^^^^^^^^^^^^^^^^^^^^^^^^^^^^^^^^^^^^^
  File "C:\Users\uqwzhon4\Anaconda3\envs\orgdb_env\Lib\site-packages\asgiref\sync.py", line 240, in __call__
    return call_result.result()
           ^^^^^^^^^^^^^^^^^^^^
  File "C:\Users\uqwzhon4\Anaconda3\envs\orgdb_env\Lib\concurrent\futures\_base.py", line 449, in result
    return self.__get_result()
           ^^^^^^^^^^^^^^^^^^^
  File "C:\Users\uqwzhon4\Anaconda3\envs\orgdb_env\Lib\concurrent\futures\_base.py", line 401, in __get_result
    raise self._exception
  File "C:\Users\uqwzhon4\Anaconda3\envs\orgdb_env\Lib\site-packages\asgiref\sync.py", line 306, in main_wrap
    result = await self.awaitable(*args, **kwargs)
                   ^^^^^^^^^^^^^^^^^^^^^^^^^^^^^^^
  File "C:\Users\uqwzhon4\Anaconda3\envs\orgdb_env\Lib\site-packages\django\views\generic\base.py", line 103, in view
    return self.dispatch(request, *args, **kwargs)
           ^^^^^^^^^^^^^^^^^^^^^^^^^^^^^^^^^^^^^^^
  File "C:\Users\uqwzhon4\Anaconda3\envs\orgdb_env\Lib\site-packages\django\contrib\auth\mixins.py", line 71, in dispatch
    if not request.user.is_authenticated:
           ^^^^^^^^^^^^^^^^^^^^^^^^^^^^^
  File "C:\Users\uqwzhon4\Anaconda3\envs\orgdb_env\Lib\site-packages\django\utils\functional.py", line 266, in inner
    self._setup()
  File "C:\Users\uqwzhon4\Anaconda3\envs\orgdb_env\Lib\site-packages\django\utils\functional.py", line 419, in _setup
    self._wrapped = self._setupfunc()
                    ^^^^^^^^^^^^^^^^^
  File "C:\Users\uqwzhon4\Anaconda3\envs\orgdb_env\Lib\site-packages\django\contrib\auth\middleware.py", line 25, in <lambda>
    request.user = SimpleLazyObject(lambda: get_user(request))
                                            ^^^^^^^^^^^^^^^^^
  File "C:\Users\uqwzhon4\Anaconda3\envs\orgdb_env\Lib\site-packages\django\contrib\auth\middleware.py", line 11, in get_user
    request._cached_user = auth.get_user(request)
                           ^^^^^^^^^^^^^^^^^^^^^^
  File "C:\Users\uqwzhon4\Anaconda3\envs\orgdb_env\Lib\site-packages\django\contrib\auth\__init__.py", line 191, in get_user
    user_id = _get_user_session_key(request)
              ^^^^^^^^^^^^^^^^^^^^^^^^^^^^^^
  File "C:\Users\uqwzhon4\Anaconda3\envs\orgdb_env\Lib\site-packages\django\contrib\auth\__init__.py", line 60, in _get_user_session_key
    return get_user_model()._meta.pk.to_python(request.session[SESSION_KEY])
                                               ~~~~~~~~~~~~~~~^^^^^^^^^^^^^
  File "C:\Users\uqwzhon4\Anaconda3\envs\orgdb_env\Lib\site-packages\django\contrib\sessions\backends\base.py", line 53, in __getitem__
    return self._session[key]
           ^^^^^^^^^^^^^
  File "C:\Users\uqwzhon4\Anaconda3\envs\orgdb_env\Lib\site-packages\django\contrib\sessions\backends\base.py", line 192, in _get_session
    self._session_cache = self.load()
                          ^^^^^^^^^^^
  File "C:\Users\uqwzhon4\Anaconda3\envs\orgdb_env\Lib\site-packages\django\contrib\sessions\backends\db.py", line 42, in load
    s = self._get_session_from_db()
        ^^^^^^^^^^^^^^^^^^^^^^^^^^^
  File "C:\Users\uqwzhon4\Anaconda3\envs\orgdb_env\Lib\site-packages\django\contrib\sessions\backends\db.py", line 32, in _get_session_from_db
    return self.model.objects.get(
           ^^^^^^^^^^^^^^^^^^^^^^^
  File "C:\Users\uqwzhon4\Anaconda3\envs\orgdb_env\Lib\site-packages\django\db\models\manager.py", line 85, in manager_method
    return getattr(self.get_queryset(), name)(*args, **kwargs)
           ^^^^^^^^^^^^^^^^^^^^^^^^^^^^^^^^^^^^^^^^^^^^^^^^^^^
  File "C:\Users\uqwzhon4\Anaconda3\envs\orgdb_env\Lib\site-packages\django\db\models\query.py", line 646, in get
    num = len(clone)
          ^^^^^^^^^^
  File "C:\Users\uqwzhon4\Anaconda3\envs\orgdb_env\Lib\site-packages\django\db\models\query.py", line 376, in __len__
    self._fetch_all()
  File "C:\Users\uqwzhon4\Anaconda3\envs\orgdb_env\Lib\site-packages\django\db\models\query.py", line 1867, in _fetch_all
    self._result_cache = list(self._iterable_class(self))
                         ^^^^^^^^^^^^^^^^^^^^^^^^^^^^^^^^
  File "C:\Users\uqwzhon4\Anaconda3\envs\orgdb_env\Lib\site-packages\django\db\models\query.py", line 87, in __iter__
    results = compiler.execute_sql(
              ^^^^^^^^^^^^^^^^^^^^^
  File "C:\Users\uqwzhon4\Anaconda3\envs\orgdb_env\Lib\site-packages\django\db\models\sql\compiler.py", line 1396, in execute_sql
    cursor = self.connection.cursor()
             ^^^^^^^^^^^^^^^^^^^^^^^^
  File "C:\Users\uqwzhon4\Anaconda3\envs\orgdb_env\Lib\site-packages\django\utils\asyncio.py", line 24, in inner
    raise SynchronousOnlyOperation(message)
django.core.exceptions.SynchronousOnlyOperation: You cannot call this from an async context - use a thread or sync_to_async.
"GET /vitekcard_list HTTP/1.1" 500 167739
Internal Server Error: /vitekcard_list
Traceback (most recent call last):
  File "C:\Users\uqwzhon4\Anaconda3\envs\orgdb_env\Lib\site-packages\django\contrib\sessions\backends\base.py", line 187, in _get_session
    return self._session_cache
           ^^^^^^^^^^^^^^^^^^^
AttributeError: 'SessionStore' object has no attribute '_session_cache'

During handling of the above exception, another exception occurred:

Traceback (most recent call last):
  File "C:\Users\uqwzhon4\Anaconda3\envs\orgdb_env\Lib\site-packages\django\core\handlers\exception.py", line 55, in inner
    response = get_response(request)
               ^^^^^^^^^^^^^^^^^^^^^
  File "C:\Users\uqwzhon4\Anaconda3\envs\orgdb_env\Lib\site-packages\django\core\handlers\base.py", line 197, in _get_response
    response = wrapped_callback(request, *callback_args, **callback_kwargs)
               ^^^^^^^^^^^^^^^^^^^^^^^^^^^^^^^^^^^^^^^^^^^^^^^^^^^^^^^^^^^^
  File "C:\Users\uqwzhon4\Anaconda3\envs\orgdb_env\Lib\site-packages\asgiref\sync.py", line 240, in __call__
    return call_result.result()
           ^^^^^^^^^^^^^^^^^^^^
  File "C:\Users\uqwzhon4\Anaconda3\envs\orgdb_env\Lib\concurrent\futures\_base.py", line 449, in result
    return self.__get_result()
           ^^^^^^^^^^^^^^^^^^^
  File "C:\Users\uqwzhon4\Anaconda3\envs\orgdb_env\Lib\concurrent\futures\_base.py", line 401, in __get_result
    raise self._exception
  File "C:\Users\uqwzhon4\Anaconda3\envs\orgdb_env\Lib\site-packages\asgiref\sync.py", line 306, in main_wrap
    result = await self.awaitable(*args, **kwargs)
                   ^^^^^^^^^^^^^^^^^^^^^^^^^^^^^^^
  File "C:\Users\uqwzhon4\Anaconda3\envs\orgdb_env\Lib\site-packages\django\views\generic\base.py", line 103, in view
    return self.dispatch(request, *args, **kwargs)
           ^^^^^^^^^^^^^^^^^^^^^^^^^^^^^^^^^^^^^^^
  File "C:\Users\uqwzhon4\Anaconda3\envs\orgdb_env\Lib\site-packages\django\contrib\auth\mixins.py", line 71, in dispatch
    if not request.user.is_authenticated:
           ^^^^^^^^^^^^^^^^^^^^^^^^^^^^^
  File "C:\Users\uqwzhon4\Anaconda3\envs\orgdb_env\Lib\site-packages\django\utils\functional.py", line 266, in inner
    self._setup()
  File "C:\Users\uqwzhon4\Anaconda3\envs\orgdb_env\Lib\site-packages\django\utils\functional.py", line 419, in _setup
    self._wrapped = self._setupfunc()
                    ^^^^^^^^^^^^^^^^^
  File "C:\Users\uqwzhon4\Anaconda3\envs\orgdb_env\Lib\site-packages\django\contrib\auth\middleware.py", line 25, in <lambda>
    request.user = SimpleLazyObject(lambda: get_user(request))
                                            ^^^^^^^^^^^^^^^^^
  File "C:\Users\uqwzhon4\Anaconda3\envs\orgdb_env\Lib\site-packages\django\contrib\auth\middleware.py", line 11, in get_user
    request._cached_user = auth.get_user(request)
                           ^^^^^^^^^^^^^^^^^^^^^^
  File "C:\Users\uqwzhon4\Anaconda3\envs\orgdb_env\Lib\site-packages\django\contrib\auth\__init__.py", line 191, in get_user
    user_id = _get_user_session_key(request)
              ^^^^^^^^^^^^^^^^^^^^^^^^^^^^^^
  File "C:\Users\uqwzhon4\Anaconda3\envs\orgdb_env\Lib\site-packages\django\contrib\auth\__init__.py", line 60, in _get_user_session_key
    return get_user_model()._meta.pk.to_python(request.session[SESSION_KEY])
                                               ~~~~~~~~~~~~~~~^^^^^^^^^^^^^
  File "C:\Users\uqwzhon4\Anaconda3\envs\orgdb_env\Lib\site-packages\django\contrib\sessions\backends\base.py", line 53, in __getitem__
    return self._session[key]
           ^^^^^^^^^^^^^
  File "C:\Users\uqwzhon4\Anaconda3\envs\orgdb_env\Lib\site-packages\django\contrib\sessions\backends\base.py", line 192, in _get_session
    self._session_cache = self.load()
                          ^^^^^^^^^^^
  File "C:\Users\uqwzhon4\Anaconda3\envs\orgdb_env\Lib\site-packages\django\contrib\sessions\backends\db.py", line 42, in load
    s = self._get_session_from_db()
        ^^^^^^^^^^^^^^^^^^^^^^^^^^^
  File "C:\Users\uqwzhon4\Anaconda3\envs\orgdb_env\Lib\site-packages\django\contrib\sessions\backends\db.py", line 32, in _get_session_from_db
    return self.model.objects.get(
           ^^^^^^^^^^^^^^^^^^^^^^^
  File "C:\Users\uqwzhon4\Anaconda3\envs\orgdb_env\Lib\site-packages\django\db\models\manager.py", line 85, in manager_method
    return getattr(self.get_queryset(), name)(*args, **kwargs)
           ^^^^^^^^^^^^^^^^^^^^^^^^^^^^^^^^^^^^^^^^^^^^^^^^^^^
  File "C:\Users\uqwzhon4\Anaconda3\envs\orgdb_env\Lib\site-packages\django\db\models\query.py", line 646, in get
    num = len(clone)
          ^^^^^^^^^^
  File "C:\Users\uqwzhon4\Anaconda3\envs\orgdb_env\Lib\site-packages\django\db\models\query.py", line 376, in __len__
    self._fetch_all()
  File "C:\Users\uqwzhon4\Anaconda3\envs\orgdb_env\Lib\site-packages\django\db\models\query.py", line 1867, in _fetch_all
    self._result_cache = list(self._iterable_class(self))
                         ^^^^^^^^^^^^^^^^^^^^^^^^^^^^^^^^
  File "C:\Users\uqwzhon4\Anaconda3\envs\orgdb_env\Lib\site-packages\django\db\models\query.py", line 87, in __iter__
    results = compiler.execute_sql(
              ^^^^^^^^^^^^^^^^^^^^^
  File "C:\Users\uqwzhon4\Anaconda3\envs\orgdb_env\Lib\site-packages\django\db\models\sql\compiler.py", line 1396, in execute_sql
    cursor = self.connection.cursor()
             ^^^^^^^^^^^^^^^^^^^^^^^^
  File "C:\Users\uqwzhon4\Anaconda3\envs\orgdb_env\Lib\site-packages\django\utils\asyncio.py", line 24, in inner
    raise SynchronousOnlyOperation(message)
django.core.exceptions.SynchronousOnlyOperation: You cannot call this from an async context - use a thread or sync_to_async.
"GET /vitekcard_list HTTP/1.1" 500 167759
Internal Server Error: /vitekcard_list
Traceback (most recent call last):
  File "C:\Users\uqwzhon4\Anaconda3\envs\orgdb_env\Lib\site-packages\django\contrib\sessions\backends\base.py", line 187, in _get_session
    return self._session_cache
           ^^^^^^^^^^^^^^^^^^^
AttributeError: 'SessionStore' object has no attribute '_session_cache'

During handling of the above exception, another exception occurred:

Traceback (most recent call last):
  File "C:\Users\uqwzhon4\Anaconda3\envs\orgdb_env\Lib\site-packages\django\core\handlers\exception.py", line 55, in inner
    response = get_response(request)
               ^^^^^^^^^^^^^^^^^^^^^
  File "C:\Users\uqwzhon4\Anaconda3\envs\orgdb_env\Lib\site-packages\django\core\handlers\base.py", line 197, in _get_response
    response = wrapped_callback(request, *callback_args, **callback_kwargs)
               ^^^^^^^^^^^^^^^^^^^^^^^^^^^^^^^^^^^^^^^^^^^^^^^^^^^^^^^^^^^^
  File "C:\Users\uqwzhon4\Anaconda3\envs\orgdb_env\Lib\site-packages\asgiref\sync.py", line 240, in __call__
    return call_result.result()
           ^^^^^^^^^^^^^^^^^^^^
  File "C:\Users\uqwzhon4\Anaconda3\envs\orgdb_env\Lib\concurrent\futures\_base.py", line 449, in result
    return self.__get_result()
           ^^^^^^^^^^^^^^^^^^^
  File "C:\Users\uqwzhon4\Anaconda3\envs\orgdb_env\Lib\concurrent\futures\_base.py", line 401, in __get_result
    raise self._exception
  File "C:\Users\uqwzhon4\Anaconda3\envs\orgdb_env\Lib\site-packages\asgiref\sync.py", line 306, in main_wrap
    result = await self.awaitable(*args, **kwargs)
                   ^^^^^^^^^^^^^^^^^^^^^^^^^^^^^^^
  File "C:\Users\uqwzhon4\Anaconda3\envs\orgdb_env\Lib\site-packages\django\views\generic\base.py", line 103, in view
    return self.dispatch(request, *args, **kwargs)
           ^^^^^^^^^^^^^^^^^^^^^^^^^^^^^^^^^^^^^^^
  File "C:\Users\uqwzhon4\Anaconda3\envs\orgdb_env\Lib\site-packages\django\contrib\auth\mixins.py", line 71, in dispatch
    if not request.user.is_authenticated:
           ^^^^^^^^^^^^^^^^^^^^^^^^^^^^^
  File "C:\Users\uqwzhon4\Anaconda3\envs\orgdb_env\Lib\site-packages\django\utils\functional.py", line 266, in inner
    self._setup()
  File "C:\Users\uqwzhon4\Anaconda3\envs\orgdb_env\Lib\site-packages\django\utils\functional.py", line 419, in _setup
    self._wrapped = self._setupfunc()
                    ^^^^^^^^^^^^^^^^^
  File "C:\Users\uqwzhon4\Anaconda3\envs\orgdb_env\Lib\site-packages\django\contrib\auth\middleware.py", line 25, in <lambda>
    request.user = SimpleLazyObject(lambda: get_user(request))
                                            ^^^^^^^^^^^^^^^^^
  File "C:\Users\uqwzhon4\Anaconda3\envs\orgdb_env\Lib\site-packages\django\contrib\auth\middleware.py", line 11, in get_user
    request._cached_user = auth.get_user(request)
                           ^^^^^^^^^^^^^^^^^^^^^^
  File "C:\Users\uqwzhon4\Anaconda3\envs\orgdb_env\Lib\site-packages\django\contrib\auth\__init__.py", line 191, in get_user
    user_id = _get_user_session_key(request)
              ^^^^^^^^^^^^^^^^^^^^^^^^^^^^^^
  File "C:\Users\uqwzhon4\Anaconda3\envs\orgdb_env\Lib\site-packages\django\contrib\auth\__init__.py", line 60, in _get_user_session_key
    return get_user_model()._meta.pk.to_python(request.session[SESSION_KEY])
                                               ~~~~~~~~~~~~~~~^^^^^^^^^^^^^
  File "C:\Users\uqwzhon4\Anaconda3\envs\orgdb_env\Lib\site-packages\django\contrib\sessions\backends\base.py", line 53, in __getitem__
    return self._session[key]
           ^^^^^^^^^^^^^
  File "C:\Users\uqwzhon4\Anaconda3\envs\orgdb_env\Lib\site-packages\django\contrib\sessions\backends\base.py", line 192, in _get_session
    self._session_cache = self.load()
                          ^^^^^^^^^^^
  File "C:\Users\uqwzhon4\Anaconda3\envs\orgdb_env\Lib\site-packages\django\contrib\sessions\backends\db.py", line 42, in load
    s = self._get_session_from_db()
        ^^^^^^^^^^^^^^^^^^^^^^^^^^^
  File "C:\Users\uqwzhon4\Anaconda3\envs\orgdb_env\Lib\site-packages\django\contrib\sessions\backends\db.py", line 32, in _get_session_from_db
    return self.model.objects.get(
           ^^^^^^^^^^^^^^^^^^^^^^^
  File "C:\Users\uqwzhon4\Anaconda3\envs\orgdb_env\Lib\site-packages\django\db\models\manager.py", line 85, in manager_method
    return getattr(self.get_queryset(), name)(*args, **kwargs)
           ^^^^^^^^^^^^^^^^^^^^^^^^^^^^^^^^^^^^^^^^^^^^^^^^^^^
  File "C:\Users\uqwzhon4\Anaconda3\envs\orgdb_env\Lib\site-packages\django\db\models\query.py", line 646, in get
    num = len(clone)
          ^^^^^^^^^^
  File "C:\Users\uqwzhon4\Anaconda3\envs\orgdb_env\Lib\site-packages\django\db\models\query.py", line 376, in __len__
    self._fetch_all()
  File "C:\Users\uqwzhon4\Anaconda3\envs\orgdb_env\Lib\site-packages\django\db\models\query.py", line 1867, in _fetch_all
    self._result_cache = list(self._iterable_class(self))
                         ^^^^^^^^^^^^^^^^^^^^^^^^^^^^^^^^
  File "C:\Users\uqwzhon4\Anaconda3\envs\orgdb_env\Lib\site-packages\django\db\models\query.py", line 87, in __iter__
    results = compiler.execute_sql(
              ^^^^^^^^^^^^^^^^^^^^^
  File "C:\Users\uqwzhon4\Anaconda3\envs\orgdb_env\Lib\site-packages\django\db\models\sql\compiler.py", line 1396, in execute_sql
    cursor = self.connection.cursor()
             ^^^^^^^^^^^^^^^^^^^^^^^^
  File "C:\Users\uqwzhon4\Anaconda3\envs\orgdb_env\Lib\site-packages\django\utils\asyncio.py", line 24, in inner
    raise SynchronousOnlyOperation(message)
django.core.exceptions.SynchronousOnlyOperation: You cannot call this from an async context - use a thread or sync_to_async.
"GET /vitekcard_list HTTP/1.1" 500 167756
Internal Server Error: /vitekcard_list
Traceback (most recent call last):
  File "C:\Users\uqwzhon4\Anaconda3\envs\orgdb_env\Lib\site-packages\django\contrib\sessions\backends\base.py", line 187, in _get_session
    return self._session_cache
           ^^^^^^^^^^^^^^^^^^^
AttributeError: 'SessionStore' object has no attribute '_session_cache'

During handling of the above exception, another exception occurred:

Traceback (most recent call last):
  File "C:\Users\uqwzhon4\Anaconda3\envs\orgdb_env\Lib\site-packages\django\core\handlers\exception.py", line 55, in inner
    response = get_response(request)
               ^^^^^^^^^^^^^^^^^^^^^
  File "C:\Users\uqwzhon4\Anaconda3\envs\orgdb_env\Lib\site-packages\django\core\handlers\base.py", line 197, in _get_response
    response = wrapped_callback(request, *callback_args, **callback_kwargs)
               ^^^^^^^^^^^^^^^^^^^^^^^^^^^^^^^^^^^^^^^^^^^^^^^^^^^^^^^^^^^^
  File "C:\Users\uqwzhon4\Anaconda3\envs\orgdb_env\Lib\site-packages\asgiref\sync.py", line 240, in __call__
    return call_result.result()
           ^^^^^^^^^^^^^^^^^^^^
  File "C:\Users\uqwzhon4\Anaconda3\envs\orgdb_env\Lib\concurrent\futures\_base.py", line 449, in result
    return self.__get_result()
           ^^^^^^^^^^^^^^^^^^^
  File "C:\Users\uqwzhon4\Anaconda3\envs\orgdb_env\Lib\concurrent\futures\_base.py", line 401, in __get_result
    raise self._exception
  File "C:\Users\uqwzhon4\Anaconda3\envs\orgdb_env\Lib\site-packages\asgiref\sync.py", line 306, in main_wrap
    result = await self.awaitable(*args, **kwargs)
                   ^^^^^^^^^^^^^^^^^^^^^^^^^^^^^^^
  File "C:\Users\uqwzhon4\Anaconda3\envs\orgdb_env\Lib\site-packages\django\views\generic\base.py", line 103, in view
    return self.dispatch(request, *args, **kwargs)
           ^^^^^^^^^^^^^^^^^^^^^^^^^^^^^^^^^^^^^^^
  File "C:\Users\uqwzhon4\Anaconda3\envs\orgdb_env\Lib\site-packages\django\contrib\auth\mixins.py", line 71, in dispatch
    if not request.user.is_authenticated:
           ^^^^^^^^^^^^^^^^^^^^^^^^^^^^^
  File "C:\Users\uqwzhon4\Anaconda3\envs\orgdb_env\Lib\site-packages\django\utils\functional.py", line 266, in inner
    self._setup()
  File "C:\Users\uqwzhon4\Anaconda3\envs\orgdb_env\Lib\site-packages\django\utils\functional.py", line 419, in _setup
    self._wrapped = self._setupfunc()
                    ^^^^^^^^^^^^^^^^^
  File "C:\Users\uqwzhon4\Anaconda3\envs\orgdb_env\Lib\site-packages\django\contrib\auth\middleware.py", line 25, in <lambda>
    request.user = SimpleLazyObject(lambda: get_user(request))
                                            ^^^^^^^^^^^^^^^^^
  File "C:\Users\uqwzhon4\Anaconda3\envs\orgdb_env\Lib\site-packages\django\contrib\auth\middleware.py", line 11, in get_user
    request._cached_user = auth.get_user(request)
                           ^^^^^^^^^^^^^^^^^^^^^^
  File "C:\Users\uqwzhon4\Anaconda3\envs\orgdb_env\Lib\site-packages\django\contrib\auth\__init__.py", line 191, in get_user
    user_id = _get_user_session_key(request)
              ^^^^^^^^^^^^^^^^^^^^^^^^^^^^^^
  File "C:\Users\uqwzhon4\Anaconda3\envs\orgdb_env\Lib\site-packages\django\contrib\auth\__init__.py", line 60, in _get_user_session_key
    return get_user_model()._meta.pk.to_python(request.session[SESSION_KEY])
                                               ~~~~~~~~~~~~~~~^^^^^^^^^^^^^
  File "C:\Users\uqwzhon4\Anaconda3\envs\orgdb_env\Lib\site-packages\django\contrib\sessions\backends\base.py", line 53, in __getitem__
    return self._session[key]
           ^^^^^^^^^^^^^
  File "C:\Users\uqwzhon4\Anaconda3\envs\orgdb_env\Lib\site-packages\django\contrib\sessions\backends\base.py", line 192, in _get_session
    self._session_cache = self.load()
                          ^^^^^^^^^^^
  File "C:\Users\uqwzhon4\Anaconda3\envs\orgdb_env\Lib\site-packages\django\contrib\sessions\backends\db.py", line 42, in load
    s = self._get_session_from_db()
        ^^^^^^^^^^^^^^^^^^^^^^^^^^^
  File "C:\Users\uqwzhon4\Anaconda3\envs\orgdb_env\Lib\site-packages\django\contrib\sessions\backends\db.py", line 32, in _get_session_from_db
    return self.model.objects.get(
           ^^^^^^^^^^^^^^^^^^^^^^^
  File "C:\Users\uqwzhon4\Anaconda3\envs\orgdb_env\Lib\site-packages\django\db\models\manager.py", line 85, in manager_method
    return getattr(self.get_queryset(), name)(*args, **kwargs)
           ^^^^^^^^^^^^^^^^^^^^^^^^^^^^^^^^^^^^^^^^^^^^^^^^^^^
  File "C:\Users\uqwzhon4\Anaconda3\envs\orgdb_env\Lib\site-packages\django\db\models\query.py", line 646, in get
    num = len(clone)
          ^^^^^^^^^^
  File "C:\Users\uqwzhon4\Anaconda3\envs\orgdb_env\Lib\site-packages\django\db\models\query.py", line 376, in __len__
    self._fetch_all()
  File "C:\Users\uqwzhon4\Anaconda3\envs\orgdb_env\Lib\site-packages\django\db\models\query.py", line 1867, in _fetch_all
    self._result_cache = list(self._iterable_class(self))
                         ^^^^^^^^^^^^^^^^^^^^^^^^^^^^^^^^
  File "C:\Users\uqwzhon4\Anaconda3\envs\orgdb_env\Lib\site-packages\django\db\models\query.py", line 87, in __iter__
    results = compiler.execute_sql(
              ^^^^^^^^^^^^^^^^^^^^^
  File "C:\Users\uqwzhon4\Anaconda3\envs\orgdb_env\Lib\site-packages\django\db\models\sql\compiler.py", line 1396, in execute_sql
    cursor = self.connection.cursor()
             ^^^^^^^^^^^^^^^^^^^^^^^^
  File "C:\Users\uqwzhon4\Anaconda3\envs\orgdb_env\Lib\site-packages\django\utils\asyncio.py", line 24, in inner
    raise SynchronousOnlyOperation(message)
django.core.exceptions.SynchronousOnlyOperation: You cannot call this from an async context - use a thread or sync_to_async.
"GET /vitekcard_list HTTP/1.1" 500 167736
Internal Server Error: /vitekcard_list
Traceback (most recent call last):
  File "C:\Users\uqwzhon4\Anaconda3\envs\orgdb_env\Lib\site-packages\django\contrib\sessions\backends\base.py", line 187, in _get_session
    return self._session_cache
           ^^^^^^^^^^^^^^^^^^^
AttributeError: 'SessionStore' object has no attribute '_session_cache'

During handling of the above exception, another exception occurred:

Traceback (most recent call last):
  File "C:\Users\uqwzhon4\Anaconda3\envs\orgdb_env\Lib\site-packages\django\core\handlers\exception.py", line 55, in inner
    response = get_response(request)
               ^^^^^^^^^^^^^^^^^^^^^
  File "C:\Users\uqwzhon4\Anaconda3\envs\orgdb_env\Lib\site-packages\django\core\handlers\base.py", line 197, in _get_response
    response = wrapped_callback(request, *callback_args, **callback_kwargs)
               ^^^^^^^^^^^^^^^^^^^^^^^^^^^^^^^^^^^^^^^^^^^^^^^^^^^^^^^^^^^^
  File "C:\Users\uqwzhon4\Anaconda3\envs\orgdb_env\Lib\site-packages\asgiref\sync.py", line 240, in __call__
    return call_result.result()
           ^^^^^^^^^^^^^^^^^^^^
  File "C:\Users\uqwzhon4\Anaconda3\envs\orgdb_env\Lib\concurrent\futures\_base.py", line 449, in result
    return self.__get_result()
           ^^^^^^^^^^^^^^^^^^^
  File "C:\Users\uqwzhon4\Anaconda3\envs\orgdb_env\Lib\concurrent\futures\_base.py", line 401, in __get_result
    raise self._exception
  File "C:\Users\uqwzhon4\Anaconda3\envs\orgdb_env\Lib\site-packages\asgiref\sync.py", line 306, in main_wrap
    result = await self.awaitable(*args, **kwargs)
                   ^^^^^^^^^^^^^^^^^^^^^^^^^^^^^^^
  File "C:\Users\uqwzhon4\Anaconda3\envs\orgdb_env\Lib\site-packages\django\views\generic\base.py", line 103, in view
    return self.dispatch(request, *args, **kwargs)
           ^^^^^^^^^^^^^^^^^^^^^^^^^^^^^^^^^^^^^^^
  File "C:\Users\uqwzhon4\Anaconda3\envs\orgdb_env\Lib\site-packages\django\contrib\auth\mixins.py", line 71, in dispatch
    if not request.user.is_authenticated:
           ^^^^^^^^^^^^^^^^^^^^^^^^^^^^^
  File "C:\Users\uqwzhon4\Anaconda3\envs\orgdb_env\Lib\site-packages\django\utils\functional.py", line 266, in inner
    self._setup()
  File "C:\Users\uqwzhon4\Anaconda3\envs\orgdb_env\Lib\site-packages\django\utils\functional.py", line 419, in _setup
    self._wrapped = self._setupfunc()
                    ^^^^^^^^^^^^^^^^^
  File "C:\Users\uqwzhon4\Anaconda3\envs\orgdb_env\Lib\site-packages\django\contrib\auth\middleware.py", line 25, in <lambda>
    request.user = SimpleLazyObject(lambda: get_user(request))
                                            ^^^^^^^^^^^^^^^^^
  File "C:\Users\uqwzhon4\Anaconda3\envs\orgdb_env\Lib\site-packages\django\contrib\auth\middleware.py", line 11, in get_user
    request._cached_user = auth.get_user(request)
                           ^^^^^^^^^^^^^^^^^^^^^^
  File "C:\Users\uqwzhon4\Anaconda3\envs\orgdb_env\Lib\site-packages\django\contrib\auth\__init__.py", line 191, in get_user
    user_id = _get_user_session_key(request)
              ^^^^^^^^^^^^^^^^^^^^^^^^^^^^^^
  File "C:\Users\uqwzhon4\Anaconda3\envs\orgdb_env\Lib\site-packages\django\contrib\auth\__init__.py", line 60, in _get_user_session_key
    return get_user_model()._meta.pk.to_python(request.session[SESSION_KEY])
                                               ~~~~~~~~~~~~~~~^^^^^^^^^^^^^
  File "C:\Users\uqwzhon4\Anaconda3\envs\orgdb_env\Lib\site-packages\django\contrib\sessions\backends\base.py", line 53, in __getitem__
    return self._session[key]
           ^^^^^^^^^^^^^
  File "C:\Users\uqwzhon4\Anaconda3\envs\orgdb_env\Lib\site-packages\django\contrib\sessions\backends\base.py", line 192, in _get_session
    self._session_cache = self.load()
                          ^^^^^^^^^^^
  File "C:\Users\uqwzhon4\Anaconda3\envs\orgdb_env\Lib\site-packages\django\contrib\sessions\backends\db.py", line 42, in load
    s = self._get_session_from_db()
        ^^^^^^^^^^^^^^^^^^^^^^^^^^^
  File "C:\Users\uqwzhon4\Anaconda3\envs\orgdb_env\Lib\site-packages\django\contrib\sessions\backends\db.py", line 32, in _get_session_from_db
    return self.model.objects.get(
           ^^^^^^^^^^^^^^^^^^^^^^^
  File "C:\Users\uqwzhon4\Anaconda3\envs\orgdb_env\Lib\site-packages\django\db\models\manager.py", line 85, in manager_method
    return getattr(self.get_queryset(), name)(*args, **kwargs)
           ^^^^^^^^^^^^^^^^^^^^^^^^^^^^^^^^^^^^^^^^^^^^^^^^^^^
  File "C:\Users\uqwzhon4\Anaconda3\envs\orgdb_env\Lib\site-packages\django\db\models\query.py", line 646, in get
    num = len(clone)
          ^^^^^^^^^^
  File "C:\Users\uqwzhon4\Anaconda3\envs\orgdb_env\Lib\site-packages\django\db\models\query.py", line 376, in __len__
    self._fetch_all()
  File "C:\Users\uqwzhon4\Anaconda3\envs\orgdb_env\Lib\site-packages\django\db\models\query.py", line 1867, in _fetch_all
    self._result_cache = list(self._iterable_class(self))
                         ^^^^^^^^^^^^^^^^^^^^^^^^^^^^^^^^
  File "C:\Users\uqwzhon4\Anaconda3\envs\orgdb_env\Lib\site-packages\django\db\models\query.py", line 87, in __iter__
    results = compiler.execute_sql(
              ^^^^^^^^^^^^^^^^^^^^^
  File "C:\Users\uqwzhon4\Anaconda3\envs\orgdb_env\Lib\site-packages\django\db\models\sql\compiler.py", line 1396, in execute_sql
    cursor = self.connection.cursor()
             ^^^^^^^^^^^^^^^^^^^^^^^^
  File "C:\Users\uqwzhon4\Anaconda3\envs\orgdb_env\Lib\site-packages\django\utils\asyncio.py", line 24, in inner
    raise SynchronousOnlyOperation(message)
django.core.exceptions.SynchronousOnlyOperation: You cannot call this from an async context - use a thread or sync_to_async.
"GET /vitekcard_list HTTP/1.1" 500 167736
Internal Server Error: /vitekcard_list
Traceback (most recent call last):
  File "C:\Users\uqwzhon4\Anaconda3\envs\orgdb_env\Lib\site-packages\django\contrib\sessions\backends\base.py", line 187, in _get_session
    return self._session_cache
           ^^^^^^^^^^^^^^^^^^^
AttributeError: 'SessionStore' object has no attribute '_session_cache'

During handling of the above exception, another exception occurred:

Traceback (most recent call last):
  File "C:\Users\uqwzhon4\Anaconda3\envs\orgdb_env\Lib\site-packages\django\core\handlers\exception.py", line 55, in inner
    response = get_response(request)
               ^^^^^^^^^^^^^^^^^^^^^
  File "C:\Users\uqwzhon4\Anaconda3\envs\orgdb_env\Lib\site-packages\django\core\handlers\base.py", line 197, in _get_response
    response = wrapped_callback(request, *callback_args, **callback_kwargs)
               ^^^^^^^^^^^^^^^^^^^^^^^^^^^^^^^^^^^^^^^^^^^^^^^^^^^^^^^^^^^^
  File "C:\Users\uqwzhon4\Anaconda3\envs\orgdb_env\Lib\site-packages\asgiref\sync.py", line 240, in __call__
    return call_result.result()
           ^^^^^^^^^^^^^^^^^^^^
  File "C:\Users\uqwzhon4\Anaconda3\envs\orgdb_env\Lib\concurrent\futures\_base.py", line 449, in result
    return self.__get_result()
           ^^^^^^^^^^^^^^^^^^^
  File "C:\Users\uqwzhon4\Anaconda3\envs\orgdb_env\Lib\concurrent\futures\_base.py", line 401, in __get_result
    raise self._exception
  File "C:\Users\uqwzhon4\Anaconda3\envs\orgdb_env\Lib\site-packages\asgiref\sync.py", line 306, in main_wrap
    result = await self.awaitable(*args, **kwargs)
                   ^^^^^^^^^^^^^^^^^^^^^^^^^^^^^^^
  File "C:\Users\uqwzhon4\Anaconda3\envs\orgdb_env\Lib\site-packages\django\views\generic\base.py", line 103, in view
    return self.dispatch(request, *args, **kwargs)
           ^^^^^^^^^^^^^^^^^^^^^^^^^^^^^^^^^^^^^^^
  File "C:\Users\uqwzhon4\Anaconda3\envs\orgdb_env\Lib\site-packages\django\contrib\auth\mixins.py", line 71, in dispatch
    if not request.user.is_authenticated:
           ^^^^^^^^^^^^^^^^^^^^^^^^^^^^^
  File "C:\Users\uqwzhon4\Anaconda3\envs\orgdb_env\Lib\site-packages\django\utils\functional.py", line 266, in inner
    self._setup()
  File "C:\Users\uqwzhon4\Anaconda3\envs\orgdb_env\Lib\site-packages\django\utils\functional.py", line 419, in _setup
    self._wrapped = self._setupfunc()
                    ^^^^^^^^^^^^^^^^^
  File "C:\Users\uqwzhon4\Anaconda3\envs\orgdb_env\Lib\site-packages\django\contrib\auth\middleware.py", line 25, in <lambda>
    request.user = SimpleLazyObject(lambda: get_user(request))
                                            ^^^^^^^^^^^^^^^^^
  File "C:\Users\uqwzhon4\Anaconda3\envs\orgdb_env\Lib\site-packages\django\contrib\auth\middleware.py", line 11, in get_user
    request._cached_user = auth.get_user(request)
                           ^^^^^^^^^^^^^^^^^^^^^^
  File "C:\Users\uqwzhon4\Anaconda3\envs\orgdb_env\Lib\site-packages\django\contrib\auth\__init__.py", line 191, in get_user
    user_id = _get_user_session_key(request)
              ^^^^^^^^^^^^^^^^^^^^^^^^^^^^^^
  File "C:\Users\uqwzhon4\Anaconda3\envs\orgdb_env\Lib\site-packages\django\contrib\auth\__init__.py", line 60, in _get_user_session_key
    return get_user_model()._meta.pk.to_python(request.session[SESSION_KEY])
                                               ~~~~~~~~~~~~~~~^^^^^^^^^^^^^
  File "C:\Users\uqwzhon4\Anaconda3\envs\orgdb_env\Lib\site-packages\django\contrib\sessions\backends\base.py", line 53, in __getitem__
    return self._session[key]
           ^^^^^^^^^^^^^
  File "C:\Users\uqwzhon4\Anaconda3\envs\orgdb_env\Lib\site-packages\django\contrib\sessions\backends\base.py", line 192, in _get_session
    self._session_cache = self.load()
                          ^^^^^^^^^^^
  File "C:\Users\uqwzhon4\Anaconda3\envs\orgdb_env\Lib\site-packages\django\contrib\sessions\backends\db.py", line 42, in load
    s = self._get_session_from_db()
        ^^^^^^^^^^^^^^^^^^^^^^^^^^^
  File "C:\Users\uqwzhon4\Anaconda3\envs\orgdb_env\Lib\site-packages\django\contrib\sessions\backends\db.py", line 32, in _get_session_from_db
    return self.model.objects.get(
           ^^^^^^^^^^^^^^^^^^^^^^^
  File "C:\Users\uqwzhon4\Anaconda3\envs\orgdb_env\Lib\site-packages\django\db\models\manager.py", line 85, in manager_method
    return getattr(self.get_queryset(), name)(*args, **kwargs)
           ^^^^^^^^^^^^^^^^^^^^^^^^^^^^^^^^^^^^^^^^^^^^^^^^^^^
  File "C:\Users\uqwzhon4\Anaconda3\envs\orgdb_env\Lib\site-packages\django\db\models\query.py", line 646, in get
    num = len(clone)
          ^^^^^^^^^^
  File "C:\Users\uqwzhon4\Anaconda3\envs\orgdb_env\Lib\site-packages\django\db\models\query.py", line 376, in __len__
    self._fetch_all()
  File "C:\Users\uqwzhon4\Anaconda3\envs\orgdb_env\Lib\site-packages\django\db\models\query.py", line 1867, in _fetch_all
    self._result_cache = list(self._iterable_class(self))
                         ^^^^^^^^^^^^^^^^^^^^^^^^^^^^^^^^
  File "C:\Users\uqwzhon4\Anaconda3\envs\orgdb_env\Lib\site-packages\django\db\models\query.py", line 87, in __iter__
    results = compiler.execute_sql(
              ^^^^^^^^^^^^^^^^^^^^^
  File "C:\Users\uqwzhon4\Anaconda3\envs\orgdb_env\Lib\site-packages\django\db\models\sql\compiler.py", line 1396, in execute_sql
    cursor = self.connection.cursor()
             ^^^^^^^^^^^^^^^^^^^^^^^^
  File "C:\Users\uqwzhon4\Anaconda3\envs\orgdb_env\Lib\site-packages\django\utils\asyncio.py", line 24, in inner
    raise SynchronousOnlyOperation(message)
django.core.exceptions.SynchronousOnlyOperation: You cannot call this from an async context - use a thread or sync_to_async.
"GET /vitekcard_list HTTP/1.1" 500 167736
Internal Server Error: /vitekcard_list
Traceback (most recent call last):
  File "C:\Users\uqwzhon4\Anaconda3\envs\orgdb_env\Lib\site-packages\django\contrib\sessions\backends\base.py", line 187, in _get_session
    return self._session_cache
           ^^^^^^^^^^^^^^^^^^^
AttributeError: 'SessionStore' object has no attribute '_session_cache'

During handling of the above exception, another exception occurred:

Traceback (most recent call last):
  File "C:\Users\uqwzhon4\Anaconda3\envs\orgdb_env\Lib\site-packages\django\core\handlers\exception.py", line 55, in inner
    response = get_response(request)
               ^^^^^^^^^^^^^^^^^^^^^
  File "C:\Users\uqwzhon4\Anaconda3\envs\orgdb_env\Lib\site-packages\django\core\handlers\base.py", line 197, in _get_response
    response = wrapped_callback(request, *callback_args, **callback_kwargs)
               ^^^^^^^^^^^^^^^^^^^^^^^^^^^^^^^^^^^^^^^^^^^^^^^^^^^^^^^^^^^^
  File "C:\Users\uqwzhon4\Anaconda3\envs\orgdb_env\Lib\site-packages\asgiref\sync.py", line 240, in __call__
    return call_result.result()
           ^^^^^^^^^^^^^^^^^^^^
  File "C:\Users\uqwzhon4\Anaconda3\envs\orgdb_env\Lib\concurrent\futures\_base.py", line 449, in result
    return self.__get_result()
           ^^^^^^^^^^^^^^^^^^^
  File "C:\Users\uqwzhon4\Anaconda3\envs\orgdb_env\Lib\concurrent\futures\_base.py", line 401, in __get_result
    raise self._exception
  File "C:\Users\uqwzhon4\Anaconda3\envs\orgdb_env\Lib\site-packages\asgiref\sync.py", line 306, in main_wrap
    result = await self.awaitable(*args, **kwargs)
                   ^^^^^^^^^^^^^^^^^^^^^^^^^^^^^^^
  File "C:\Users\uqwzhon4\Anaconda3\envs\orgdb_env\Lib\site-packages\django\views\generic\base.py", line 103, in view
    return self.dispatch(request, *args, **kwargs)
           ^^^^^^^^^^^^^^^^^^^^^^^^^^^^^^^^^^^^^^^
  File "C:\Users\uqwzhon4\Anaconda3\envs\orgdb_env\Lib\site-packages\django\contrib\auth\mixins.py", line 71, in dispatch
    if not request.user.is_authenticated:
           ^^^^^^^^^^^^^^^^^^^^^^^^^^^^^
  File "C:\Users\uqwzhon4\Anaconda3\envs\orgdb_env\Lib\site-packages\django\utils\functional.py", line 266, in inner
    self._setup()
  File "C:\Users\uqwzhon4\Anaconda3\envs\orgdb_env\Lib\site-packages\django\utils\functional.py", line 419, in _setup
    self._wrapped = self._setupfunc()
                    ^^^^^^^^^^^^^^^^^
  File "C:\Users\uqwzhon4\Anaconda3\envs\orgdb_env\Lib\site-packages\django\contrib\auth\middleware.py", line 25, in <lambda>
    request.user = SimpleLazyObject(lambda: get_user(request))
                                            ^^^^^^^^^^^^^^^^^
  File "C:\Users\uqwzhon4\Anaconda3\envs\orgdb_env\Lib\site-packages\django\contrib\auth\middleware.py", line 11, in get_user
    request._cached_user = auth.get_user(request)
                           ^^^^^^^^^^^^^^^^^^^^^^
  File "C:\Users\uqwzhon4\Anaconda3\envs\orgdb_env\Lib\site-packages\django\contrib\auth\__init__.py", line 191, in get_user
    user_id = _get_user_session_key(request)
              ^^^^^^^^^^^^^^^^^^^^^^^^^^^^^^
  File "C:\Users\uqwzhon4\Anaconda3\envs\orgdb_env\Lib\site-packages\django\contrib\auth\__init__.py", line 60, in _get_user_session_key
    return get_user_model()._meta.pk.to_python(request.session[SESSION_KEY])
                                               ~~~~~~~~~~~~~~~^^^^^^^^^^^^^
  File "C:\Users\uqwzhon4\Anaconda3\envs\orgdb_env\Lib\site-packages\django\contrib\sessions\backends\base.py", line 53, in __getitem__
    return self._session[key]
           ^^^^^^^^^^^^^
  File "C:\Users\uqwzhon4\Anaconda3\envs\orgdb_env\Lib\site-packages\django\contrib\sessions\backends\base.py", line 192, in _get_session
    self._session_cache = self.load()
                          ^^^^^^^^^^^
  File "C:\Users\uqwzhon4\Anaconda3\envs\orgdb_env\Lib\site-packages\django\contrib\sessions\backends\db.py", line 42, in load
    s = self._get_session_from_db()
        ^^^^^^^^^^^^^^^^^^^^^^^^^^^
  File "C:\Users\uqwzhon4\Anaconda3\envs\orgdb_env\Lib\site-packages\django\contrib\sessions\backends\db.py", line 32, in _get_session_from_db
    return self.model.objects.get(
           ^^^^^^^^^^^^^^^^^^^^^^^
  File "C:\Users\uqwzhon4\Anaconda3\envs\orgdb_env\Lib\site-packages\django\db\models\manager.py", line 85, in manager_method
    return getattr(self.get_queryset(), name)(*args, **kwargs)
           ^^^^^^^^^^^^^^^^^^^^^^^^^^^^^^^^^^^^^^^^^^^^^^^^^^^
  File "C:\Users\uqwzhon4\Anaconda3\envs\orgdb_env\Lib\site-packages\django\db\models\query.py", line 646, in get
    num = len(clone)
          ^^^^^^^^^^
  File "C:\Users\uqwzhon4\Anaconda3\envs\orgdb_env\Lib\site-packages\django\db\models\query.py", line 376, in __len__
    self._fetch_all()
  File "C:\Users\uqwzhon4\Anaconda3\envs\orgdb_env\Lib\site-packages\django\db\models\query.py", line 1867, in _fetch_all
    self._result_cache = list(self._iterable_class(self))
                         ^^^^^^^^^^^^^^^^^^^^^^^^^^^^^^^^
  File "C:\Users\uqwzhon4\Anaconda3\envs\orgdb_env\Lib\site-packages\django\db\models\query.py", line 87, in __iter__
    results = compiler.execute_sql(
              ^^^^^^^^^^^^^^^^^^^^^
  File "C:\Users\uqwzhon4\Anaconda3\envs\orgdb_env\Lib\site-packages\django\db\models\sql\compiler.py", line 1396, in execute_sql
    cursor = self.connection.cursor()
             ^^^^^^^^^^^^^^^^^^^^^^^^
  File "C:\Users\uqwzhon4\Anaconda3\envs\orgdb_env\Lib\site-packages\django\utils\asyncio.py", line 24, in inner
    raise SynchronousOnlyOperation(message)
django.core.exceptions.SynchronousOnlyOperation: You cannot call this from an async context - use a thread or sync_to_async.
"GET /vitekcard_list HTTP/1.1" 500 167733
Internal Server Error: /vitekcard_list
Traceback (most recent call last):
  File "C:\Users\uqwzhon4\Anaconda3\envs\orgdb_env\Lib\site-packages\django\contrib\sessions\backends\base.py", line 187, in _get_session
    return self._session_cache
           ^^^^^^^^^^^^^^^^^^^
AttributeError: 'SessionStore' object has no attribute '_session_cache'

During handling of the above exception, another exception occurred:

Traceback (most recent call last):
  File "C:\Users\uqwzhon4\Anaconda3\envs\orgdb_env\Lib\site-packages\django\core\handlers\exception.py", line 55, in inner
    response = get_response(request)
               ^^^^^^^^^^^^^^^^^^^^^
  File "C:\Users\uqwzhon4\Anaconda3\envs\orgdb_env\Lib\site-packages\django\core\handlers\base.py", line 197, in _get_response
    response = wrapped_callback(request, *callback_args, **callback_kwargs)
               ^^^^^^^^^^^^^^^^^^^^^^^^^^^^^^^^^^^^^^^^^^^^^^^^^^^^^^^^^^^^
  File "C:\Users\uqwzhon4\Anaconda3\envs\orgdb_env\Lib\site-packages\asgiref\sync.py", line 240, in __call__
    return call_result.result()
           ^^^^^^^^^^^^^^^^^^^^
  File "C:\Users\uqwzhon4\Anaconda3\envs\orgdb_env\Lib\concurrent\futures\_base.py", line 449, in result
    return self.__get_result()
           ^^^^^^^^^^^^^^^^^^^
  File "C:\Users\uqwzhon4\Anaconda3\envs\orgdb_env\Lib\concurrent\futures\_base.py", line 401, in __get_result
    raise self._exception
  File "C:\Users\uqwzhon4\Anaconda3\envs\orgdb_env\Lib\site-packages\asgiref\sync.py", line 306, in main_wrap
    result = await self.awaitable(*args, **kwargs)
                   ^^^^^^^^^^^^^^^^^^^^^^^^^^^^^^^
  File "C:\Users\uqwzhon4\Anaconda3\envs\orgdb_env\Lib\site-packages\django\views\generic\base.py", line 103, in view
    return self.dispatch(request, *args, **kwargs)
           ^^^^^^^^^^^^^^^^^^^^^^^^^^^^^^^^^^^^^^^
  File "C:\Users\uqwzhon4\Anaconda3\envs\orgdb_env\Lib\site-packages\django\contrib\auth\mixins.py", line 71, in dispatch
    if not request.user.is_authenticated:
           ^^^^^^^^^^^^^^^^^^^^^^^^^^^^^
  File "C:\Users\uqwzhon4\Anaconda3\envs\orgdb_env\Lib\site-packages\django\utils\functional.py", line 266, in inner
    self._setup()
  File "C:\Users\uqwzhon4\Anaconda3\envs\orgdb_env\Lib\site-packages\django\utils\functional.py", line 419, in _setup
    self._wrapped = self._setupfunc()
                    ^^^^^^^^^^^^^^^^^
  File "C:\Users\uqwzhon4\Anaconda3\envs\orgdb_env\Lib\site-packages\django\contrib\auth\middleware.py", line 25, in <lambda>
    request.user = SimpleLazyObject(lambda: get_user(request))
                                            ^^^^^^^^^^^^^^^^^
  File "C:\Users\uqwzhon4\Anaconda3\envs\orgdb_env\Lib\site-packages\django\contrib\auth\middleware.py", line 11, in get_user
    request._cached_user = auth.get_user(request)
                           ^^^^^^^^^^^^^^^^^^^^^^
  File "C:\Users\uqwzhon4\Anaconda3\envs\orgdb_env\Lib\site-packages\django\contrib\auth\__init__.py", line 191, in get_user
    user_id = _get_user_session_key(request)
              ^^^^^^^^^^^^^^^^^^^^^^^^^^^^^^
  File "C:\Users\uqwzhon4\Anaconda3\envs\orgdb_env\Lib\site-packages\django\contrib\auth\__init__.py", line 60, in _get_user_session_key
    return get_user_model()._meta.pk.to_python(request.session[SESSION_KEY])
                                               ~~~~~~~~~~~~~~~^^^^^^^^^^^^^
  File "C:\Users\uqwzhon4\Anaconda3\envs\orgdb_env\Lib\site-packages\django\contrib\sessions\backends\base.py", line 53, in __getitem__
    return self._session[key]
           ^^^^^^^^^^^^^
  File "C:\Users\uqwzhon4\Anaconda3\envs\orgdb_env\Lib\site-packages\django\contrib\sessions\backends\base.py", line 192, in _get_session
    self._session_cache = self.load()
                          ^^^^^^^^^^^
  File "C:\Users\uqwzhon4\Anaconda3\envs\orgdb_env\Lib\site-packages\django\contrib\sessions\backends\db.py", line 42, in load
    s = self._get_session_from_db()
        ^^^^^^^^^^^^^^^^^^^^^^^^^^^
  File "C:\Users\uqwzhon4\Anaconda3\envs\orgdb_env\Lib\site-packages\django\contrib\sessions\backends\db.py", line 32, in _get_session_from_db
    return self.model.objects.get(
           ^^^^^^^^^^^^^^^^^^^^^^^
  File "C:\Users\uqwzhon4\Anaconda3\envs\orgdb_env\Lib\site-packages\django\db\models\manager.py", line 85, in manager_method
    return getattr(self.get_queryset(), name)(*args, **kwargs)
           ^^^^^^^^^^^^^^^^^^^^^^^^^^^^^^^^^^^^^^^^^^^^^^^^^^^
  File "C:\Users\uqwzhon4\Anaconda3\envs\orgdb_env\Lib\site-packages\django\db\models\query.py", line 646, in get
    num = len(clone)
          ^^^^^^^^^^
  File "C:\Users\uqwzhon4\Anaconda3\envs\orgdb_env\Lib\site-packages\django\db\models\query.py", line 376, in __len__
    self._fetch_all()
  File "C:\Users\uqwzhon4\Anaconda3\envs\orgdb_env\Lib\site-packages\django\db\models\query.py", line 1867, in _fetch_all
    self._result_cache = list(self._iterable_class(self))
                         ^^^^^^^^^^^^^^^^^^^^^^^^^^^^^^^^
  File "C:\Users\uqwzhon4\Anaconda3\envs\orgdb_env\Lib\site-packages\django\db\models\query.py", line 87, in __iter__
    results = compiler.execute_sql(
              ^^^^^^^^^^^^^^^^^^^^^
  File "C:\Users\uqwzhon4\Anaconda3\envs\orgdb_env\Lib\site-packages\django\db\models\sql\compiler.py", line 1396, in execute_sql
    cursor = self.connection.cursor()
             ^^^^^^^^^^^^^^^^^^^^^^^^
  File "C:\Users\uqwzhon4\Anaconda3\envs\orgdb_env\Lib\site-packages\django\utils\asyncio.py", line 24, in inner
    raise SynchronousOnlyOperation(message)
django.core.exceptions.SynchronousOnlyOperation: You cannot call this from an async context - use a thread or sync_to_async.
"GET /vitekcard_list HTTP/1.1" 500 167736
Internal Server Error: /vitekcard_list
Traceback (most recent call last):
  File "C:\Users\uqwzhon4\Anaconda3\envs\orgdb_env\Lib\site-packages\django\contrib\sessions\backends\base.py", line 187, in _get_session
    return self._session_cache
           ^^^^^^^^^^^^^^^^^^^
AttributeError: 'SessionStore' object has no attribute '_session_cache'

During handling of the above exception, another exception occurred:

Traceback (most recent call last):
  File "C:\Users\uqwzhon4\Anaconda3\envs\orgdb_env\Lib\site-packages\django\core\handlers\exception.py", line 55, in inner
    response = get_response(request)
               ^^^^^^^^^^^^^^^^^^^^^
  File "C:\Users\uqwzhon4\Anaconda3\envs\orgdb_env\Lib\site-packages\django\core\handlers\base.py", line 197, in _get_response
    response = wrapped_callback(request, *callback_args, **callback_kwargs)
               ^^^^^^^^^^^^^^^^^^^^^^^^^^^^^^^^^^^^^^^^^^^^^^^^^^^^^^^^^^^^
  File "C:\Users\uqwzhon4\Anaconda3\envs\orgdb_env\Lib\site-packages\asgiref\sync.py", line 240, in __call__
    return call_result.result()
           ^^^^^^^^^^^^^^^^^^^^
  File "C:\Users\uqwzhon4\Anaconda3\envs\orgdb_env\Lib\concurrent\futures\_base.py", line 449, in result
    return self.__get_result()
           ^^^^^^^^^^^^^^^^^^^
  File "C:\Users\uqwzhon4\Anaconda3\envs\orgdb_env\Lib\concurrent\futures\_base.py", line 401, in __get_result
    raise self._exception
  File "C:\Users\uqwzhon4\Anaconda3\envs\orgdb_env\Lib\site-packages\asgiref\sync.py", line 306, in main_wrap
    result = await self.awaitable(*args, **kwargs)
                   ^^^^^^^^^^^^^^^^^^^^^^^^^^^^^^^
  File "C:\Users\uqwzhon4\Anaconda3\envs\orgdb_env\Lib\site-packages\django\views\generic\base.py", line 103, in view
    return self.dispatch(request, *args, **kwargs)
           ^^^^^^^^^^^^^^^^^^^^^^^^^^^^^^^^^^^^^^^
  File "C:\Users\uqwzhon4\Anaconda3\envs\orgdb_env\Lib\site-packages\django\contrib\auth\mixins.py", line 71, in dispatch
    if not request.user.is_authenticated:
           ^^^^^^^^^^^^^^^^^^^^^^^^^^^^^
  File "C:\Users\uqwzhon4\Anaconda3\envs\orgdb_env\Lib\site-packages\django\utils\functional.py", line 266, in inner
    self._setup()
  File "C:\Users\uqwzhon4\Anaconda3\envs\orgdb_env\Lib\site-packages\django\utils\functional.py", line 419, in _setup
    self._wrapped = self._setupfunc()
                    ^^^^^^^^^^^^^^^^^
  File "C:\Users\uqwzhon4\Anaconda3\envs\orgdb_env\Lib\site-packages\django\contrib\auth\middleware.py", line 25, in <lambda>
    request.user = SimpleLazyObject(lambda: get_user(request))
                                            ^^^^^^^^^^^^^^^^^
  File "C:\Users\uqwzhon4\Anaconda3\envs\orgdb_env\Lib\site-packages\django\contrib\auth\middleware.py", line 11, in get_user
    request._cached_user = auth.get_user(request)
                           ^^^^^^^^^^^^^^^^^^^^^^
  File "C:\Users\uqwzhon4\Anaconda3\envs\orgdb_env\Lib\site-packages\django\contrib\auth\__init__.py", line 191, in get_user
    user_id = _get_user_session_key(request)
              ^^^^^^^^^^^^^^^^^^^^^^^^^^^^^^
  File "C:\Users\uqwzhon4\Anaconda3\envs\orgdb_env\Lib\site-packages\django\contrib\auth\__init__.py", line 60, in _get_user_session_key
    return get_user_model()._meta.pk.to_python(request.session[SESSION_KEY])
                                               ~~~~~~~~~~~~~~~^^^^^^^^^^^^^
  File "C:\Users\uqwzhon4\Anaconda3\envs\orgdb_env\Lib\site-packages\django\contrib\sessions\backends\base.py", line 53, in __getitem__
    return self._session[key]
           ^^^^^^^^^^^^^
  File "C:\Users\uqwzhon4\Anaconda3\envs\orgdb_env\Lib\site-packages\django\contrib\sessions\backends\base.py", line 192, in _get_session
    self._session_cache = self.load()
                          ^^^^^^^^^^^
  File "C:\Users\uqwzhon4\Anaconda3\envs\orgdb_env\Lib\site-packages\django\contrib\sessions\backends\db.py", line 42, in load
    s = self._get_session_from_db()
        ^^^^^^^^^^^^^^^^^^^^^^^^^^^
  File "C:\Users\uqwzhon4\Anaconda3\envs\orgdb_env\Lib\site-packages\django\contrib\sessions\backends\db.py", line 32, in _get_session_from_db
    return self.model.objects.get(
           ^^^^^^^^^^^^^^^^^^^^^^^
  File "C:\Users\uqwzhon4\Anaconda3\envs\orgdb_env\Lib\site-packages\django\db\models\manager.py", line 85, in manager_method
    return getattr(self.get_queryset(), name)(*args, **kwargs)
           ^^^^^^^^^^^^^^^^^^^^^^^^^^^^^^^^^^^^^^^^^^^^^^^^^^^
  File "C:\Users\uqwzhon4\Anaconda3\envs\orgdb_env\Lib\site-packages\django\db\models\query.py", line 646, in get
    num = len(clone)
          ^^^^^^^^^^
  File "C:\Users\uqwzhon4\Anaconda3\envs\orgdb_env\Lib\site-packages\django\db\models\query.py", line 376, in __len__
    self._fetch_all()
  File "C:\Users\uqwzhon4\Anaconda3\envs\orgdb_env\Lib\site-packages\django\db\models\query.py", line 1867, in _fetch_all
    self._result_cache = list(self._iterable_class(self))
                         ^^^^^^^^^^^^^^^^^^^^^^^^^^^^^^^^
  File "C:\Users\uqwzhon4\Anaconda3\envs\orgdb_env\Lib\site-packages\django\db\models\query.py", line 87, in __iter__
    results = compiler.execute_sql(
              ^^^^^^^^^^^^^^^^^^^^^
  File "C:\Users\uqwzhon4\Anaconda3\envs\orgdb_env\Lib\site-packages\django\db\models\sql\compiler.py", line 1396, in execute_sql
    cursor = self.connection.cursor()
             ^^^^^^^^^^^^^^^^^^^^^^^^
  File "C:\Users\uqwzhon4\Anaconda3\envs\orgdb_env\Lib\site-packages\django\utils\asyncio.py", line 24, in inner
    raise SynchronousOnlyOperation(message)
django.core.exceptions.SynchronousOnlyOperation: You cannot call this from an async context - use a thread or sync_to_async.
"GET /vitekcard_list HTTP/1.1" 500 167736
Internal Server Error: /vitekcard_list
Traceback (most recent call last):
  File "C:\Users\uqwzhon4\Anaconda3\envs\orgdb_env\Lib\site-packages\django\core\handlers\exception.py", line 55, in inner
    response = get_response(request)
               ^^^^^^^^^^^^^^^^^^^^^
  File "C:\Users\uqwzhon4\Anaconda3\envs\orgdb_env\Lib\site-packages\django\core\handlers\base.py", line 197, in _get_response
    response = wrapped_callback(request, *callback_args, **callback_kwargs)
               ^^^^^^^^^^^^^^^^^^^^^^^^^^^^^^^^^^^^^^^^^^^^^^^^^^^^^^^^^^^^
  File "C:\Users\uqwzhon4\Anaconda3\envs\orgdb_env\Lib\site-packages\django\views\generic\base.py", line 103, in view
    return self.dispatch(request, *args, **kwargs)
           ^^^^^^^^^^^^^^^^^^^^^^^^^^^^^^^^^^^^^^^
  File "C:\Users\uqwzhon4\Anaconda3\envs\orgdb_env\Lib\site-packages\django\contrib\auth\mixins.py", line 73, in dispatch
    return super().dispatch(request, *args, **kwargs)
           ^^^^^^^^^^^^^^^^^^^^^^^^^^^^^^^^^^^^^^^^^^
  File "C:\Users\uqwzhon4\Anaconda3\envs\orgdb_env\Lib\site-packages\django\views\generic\base.py", line 142, in dispatch
    return handler(request, *args, **kwargs)
           ^^^^^^^^^^^^^^^^^^^^^^^^^^^^^^^^^
  File "C:\Users\uqwzhon4\Anaconda3\envs\orgdb_env\Lib\site-packages\django\views\generic\list.py", line 174, in get
    context = self.get_context_data()
              ^^^^^^^^^^^^^^^^^^^^^^^
  File "C:\Users\uqwzhon4\Project\adjCOADD\ddrug\views.py", line 139, in get_context_data
    context['defaultcolumns1']='expiry_date'
    ~~~~~~~^^^^^^^^^^^^^^^^^^^
TypeError: 'coroutine' object does not support item assignment
"GET /vitekcard_list HTTP/1.1" 500 89856
Internal Server Error: /vitekcard_list
Traceback (most recent call last):
  File "C:\Users\uqwzhon4\Anaconda3\envs\orgdb_env\Lib\site-packages\django\core\handlers\exception.py", line 55, in inner
    response = get_response(request)
               ^^^^^^^^^^^^^^^^^^^^^
  File "C:\Users\uqwzhon4\Anaconda3\envs\orgdb_env\Lib\site-packages\django\core\handlers\base.py", line 197, in _get_response
    response = wrapped_callback(request, *callback_args, **callback_kwargs)
               ^^^^^^^^^^^^^^^^^^^^^^^^^^^^^^^^^^^^^^^^^^^^^^^^^^^^^^^^^^^^
  File "C:\Users\uqwzhon4\Anaconda3\envs\orgdb_env\Lib\site-packages\django\views\generic\base.py", line 103, in view
    return self.dispatch(request, *args, **kwargs)
           ^^^^^^^^^^^^^^^^^^^^^^^^^^^^^^^^^^^^^^^
  File "C:\Users\uqwzhon4\Anaconda3\envs\orgdb_env\Lib\site-packages\django\contrib\auth\mixins.py", line 73, in dispatch
    return super().dispatch(request, *args, **kwargs)
           ^^^^^^^^^^^^^^^^^^^^^^^^^^^^^^^^^^^^^^^^^^
  File "C:\Users\uqwzhon4\Anaconda3\envs\orgdb_env\Lib\site-packages\django\views\generic\base.py", line 142, in dispatch
    return handler(request, *args, **kwargs)
           ^^^^^^^^^^^^^^^^^^^^^^^^^^^^^^^^^
  File "C:\Users\uqwzhon4\Project\adjCOADD\ddrug\views.py", line 172, in post
    query_send=serializers.serialize('json', querydata.values() )
               ^^^^^^^^^^^^^^^^^^^^^^^^^^^^^^^^^^^^^^^^^^^^^^^^^^
  File "C:\Users\uqwzhon4\Anaconda3\envs\orgdb_env\Lib\site-packages\django\core\serializers\__init__.py", line 134, in serialize
    s.serialize(queryset, **options)
  File "C:\Users\uqwzhon4\Anaconda3\envs\orgdb_env\Lib\site-packages\django\core\serializers\base.py", line 136, in serialize
    concrete_model = obj._meta.concrete_model
                     ^^^^^^^^^
AttributeError: 'dict' object has no attribute '_meta'
"POST /vitekcard_list HTTP/1.1" 500 112526
Internal Server Error: /vitekcard_list
Traceback (most recent call last):
  File "C:\Users\uqwzhon4\Anaconda3\envs\orgdb_env\Lib\site-packages\django\core\handlers\exception.py", line 55, in inner
    response = get_response(request)
               ^^^^^^^^^^^^^^^^^^^^^
  File "C:\Users\uqwzhon4\Anaconda3\envs\orgdb_env\Lib\site-packages\django\core\handlers\base.py", line 197, in _get_response
    response = wrapped_callback(request, *callback_args, **callback_kwargs)
               ^^^^^^^^^^^^^^^^^^^^^^^^^^^^^^^^^^^^^^^^^^^^^^^^^^^^^^^^^^^^
  File "C:\Users\uqwzhon4\Anaconda3\envs\orgdb_env\Lib\site-packages\django\views\generic\base.py", line 103, in view
    return self.dispatch(request, *args, **kwargs)
           ^^^^^^^^^^^^^^^^^^^^^^^^^^^^^^^^^^^^^^^
  File "C:\Users\uqwzhon4\Anaconda3\envs\orgdb_env\Lib\site-packages\django\contrib\auth\mixins.py", line 73, in dispatch
    return super().dispatch(request, *args, **kwargs)
           ^^^^^^^^^^^^^^^^^^^^^^^^^^^^^^^^^^^^^^^^^^
  File "C:\Users\uqwzhon4\Anaconda3\envs\orgdb_env\Lib\site-packages\django\views\generic\base.py", line 142, in dispatch
    return handler(request, *args, **kwargs)
           ^^^^^^^^^^^^^^^^^^^^^^^^^^^^^^^^^
  File "C:\Users\uqwzhon4\Project\adjCOADD\ddrug\views.py", line 172, in post
    query_send=serializers.serialize('json', querydata.values, fields=('expiry_date', 'analysis_time', 'proc_date') )
               ^^^^^^^^^^^^^^^^^^^^^^^^^^^^^^^^^^^^^^^^^^^^^^^^^^^^^^^^^^^^^^^^^^^^^^^^^^^^^^^^^^^^^^^^^^^^^^^^^^^^^^
  File "C:\Users\uqwzhon4\Anaconda3\envs\orgdb_env\Lib\site-packages\django\core\serializers\__init__.py", line 134, in serialize
    s.serialize(queryset, **options)
  File "C:\Users\uqwzhon4\Anaconda3\envs\orgdb_env\Lib\site-packages\django\core\serializers\base.py", line 132, in serialize
    for count, obj in enumerate(queryset, start=1):
                      ^^^^^^^^^^^^^^^^^^^^^^^^^^^^
TypeError: 'method' object is not iterable
"POST /vitekcard_list HTTP/1.1" 500 101922
Internal Server Error: /vitekcard_list
Traceback (most recent call last):
  File "C:\Users\uqwzhon4\Anaconda3\envs\orgdb_env\Lib\site-packages\django\core\handlers\exception.py", line 55, in inner
    response = get_response(request)
               ^^^^^^^^^^^^^^^^^^^^^
  File "C:\Users\uqwzhon4\Anaconda3\envs\orgdb_env\Lib\site-packages\django\core\handlers\base.py", line 197, in _get_response
    response = wrapped_callback(request, *callback_args, **callback_kwargs)
               ^^^^^^^^^^^^^^^^^^^^^^^^^^^^^^^^^^^^^^^^^^^^^^^^^^^^^^^^^^^^
  File "C:\Users\uqwzhon4\Anaconda3\envs\orgdb_env\Lib\site-packages\django\views\generic\base.py", line 103, in view
    return self.dispatch(request, *args, **kwargs)
           ^^^^^^^^^^^^^^^^^^^^^^^^^^^^^^^^^^^^^^^
  File "C:\Users\uqwzhon4\Anaconda3\envs\orgdb_env\Lib\site-packages\django\contrib\auth\mixins.py", line 73, in dispatch
    return super().dispatch(request, *args, **kwargs)
           ^^^^^^^^^^^^^^^^^^^^^^^^^^^^^^^^^^^^^^^^^^
  File "C:\Users\uqwzhon4\Anaconda3\envs\orgdb_env\Lib\site-packages\django\views\generic\base.py", line 142, in dispatch
    return handler(request, *args, **kwargs)
           ^^^^^^^^^^^^^^^^^^^^^^^^^^^^^^^^^
  File "C:\Users\uqwzhon4\Project\adjCOADD\ddrug\views.py", line 173, in post
    query_send=json.dumps(list(querydata.values()), cls=DjangoJSONEncoder)
                                                       ^^^^^^^^^^^^^^^^^
NameError: name 'DjangoJSONEncoder' is not defined
"POST /vitekcard_list HTTP/1.1" 500 90060
Internal Server Error: /vitekcard_list
Traceback (most recent call last):
  File "C:\Users\uqwzhon4\Anaconda3\envs\orgdb_env\Lib\site-packages\django\core\handlers\exception.py", line 55, in inner
    response = get_response(request)
               ^^^^^^^^^^^^^^^^^^^^^
  File "C:\Users\uqwzhon4\Anaconda3\envs\orgdb_env\Lib\site-packages\django\core\handlers\base.py", line 197, in _get_response
    response = wrapped_callback(request, *callback_args, **callback_kwargs)
               ^^^^^^^^^^^^^^^^^^^^^^^^^^^^^^^^^^^^^^^^^^^^^^^^^^^^^^^^^^^^
  File "C:\Users\uqwzhon4\Anaconda3\envs\orgdb_env\Lib\site-packages\django\views\generic\base.py", line 103, in view
    return self.dispatch(request, *args, **kwargs)
           ^^^^^^^^^^^^^^^^^^^^^^^^^^^^^^^^^^^^^^^
  File "C:\Users\uqwzhon4\Anaconda3\envs\orgdb_env\Lib\site-packages\django\contrib\auth\mixins.py", line 73, in dispatch
    return super().dispatch(request, *args, **kwargs)
           ^^^^^^^^^^^^^^^^^^^^^^^^^^^^^^^^^^^^^^^^^^
  File "C:\Users\uqwzhon4\Anaconda3\envs\orgdb_env\Lib\site-packages\django\views\generic\base.py", line 142, in dispatch
    return handler(request, *args, **kwargs)
           ^^^^^^^^^^^^^^^^^^^^^^^^^^^^^^^^^
  File "C:\Users\uqwzhon4\Project\adjCOADD\ddrug\views.py", line 176, in post
    if values:
       ^^^^^^
NameError: name 'values' is not defined
"POST /vitekcard_list HTTP/1.1" 500 97238
