Not Found: /favicon.ico
"GET /favicon.ico HTTP/1.1" 404 11457
Internal Server Error: /admin/apputil/dictionary/add/
Traceback (most recent call last):
  File "/home/wz/anaconda3/envs/coadd_env/lib/python3.10/site-packages/django/db/backends/utils.py", line 89, in _execute
    return self.cursor.execute(sql, params)
psycopg2.errors.NotNullViolation: null value in column "urlname" violates not-null constraint
DETAIL:  Failing row contains (0, 2023-02-05 11:09:00.994572+00, null, null, test, test, test, orgdb, null, null, null).


The above exception was the direct cause of the following exception:

Traceback (most recent call last):
  File "/home/wz/anaconda3/envs/coadd_env/lib/python3.10/site-packages/django/core/handlers/exception.py", line 55, in inner
    response = get_response(request)
  File "/home/wz/anaconda3/envs/coadd_env/lib/python3.10/site-packages/django/core/handlers/base.py", line 197, in _get_response
    response = wrapped_callback(request, *callback_args, **callback_kwargs)
  File "/home/wz/anaconda3/envs/coadd_env/lib/python3.10/site-packages/django/contrib/admin/options.py", line 686, in wrapper
    return self.admin_site.admin_view(view)(*args, **kwargs)
  File "/home/wz/anaconda3/envs/coadd_env/lib/python3.10/site-packages/django/utils/decorators.py", line 133, in _wrapped_view
    response = view_func(request, *args, **kwargs)
  File "/home/wz/anaconda3/envs/coadd_env/lib/python3.10/site-packages/django/views/decorators/cache.py", line 62, in _wrapped_view_func
    response = view_func(request, *args, **kwargs)
  File "/home/wz/anaconda3/envs/coadd_env/lib/python3.10/site-packages/django/contrib/admin/sites.py", line 242, in inner
    return view(request, *args, **kwargs)
  File "/home/wz/anaconda3/envs/coadd_env/lib/python3.10/site-packages/django/contrib/admin/options.py", line 1890, in add_view
    return self.changeform_view(request, None, form_url, extra_context)
  File "/home/wz/anaconda3/envs/coadd_env/lib/python3.10/site-packages/django/utils/decorators.py", line 46, in _wrapper
    return bound_method(*args, **kwargs)
  File "/home/wz/anaconda3/envs/coadd_env/lib/python3.10/site-packages/django/utils/decorators.py", line 133, in _wrapped_view
    response = view_func(request, *args, **kwargs)
  File "/home/wz/anaconda3/envs/coadd_env/lib/python3.10/site-packages/django/contrib/admin/options.py", line 1750, in changeform_view
    return self._changeform_view(request, object_id, form_url, extra_context)
  File "/home/wz/anaconda3/envs/coadd_env/lib/python3.10/site-packages/django/contrib/admin/options.py", line 1802, in _changeform_view
    self.save_model(request, new_object, form, not add)
  File "/home/wz/anaconda3/envs/coadd_env/lib/python3.10/site-packages/django/contrib/admin/options.py", line 1225, in save_model
    obj.save()
  File "/home/wz/adjCOADD/apputil/models.py", line 181, in save
    super(AuditModel,self).save(*args, **kwargs)
  File "/home/wz/anaconda3/envs/coadd_env/lib/python3.10/site-packages/django/db/models/base.py", line 831, in save
    self.save_base(
  File "/home/wz/anaconda3/envs/coadd_env/lib/python3.10/site-packages/django/db/models/base.py", line 882, in save_base
    updated = self._save_table(
  File "/home/wz/anaconda3/envs/coadd_env/lib/python3.10/site-packages/django/db/models/base.py", line 1025, in _save_table
    results = self._do_insert(
  File "/home/wz/anaconda3/envs/coadd_env/lib/python3.10/site-packages/django/db/models/base.py", line 1066, in _do_insert
    return manager._insert(
  File "/home/wz/anaconda3/envs/coadd_env/lib/python3.10/site-packages/django/db/models/manager.py", line 85, in manager_method
    return getattr(self.get_queryset(), name)(*args, **kwargs)
  File "/home/wz/anaconda3/envs/coadd_env/lib/python3.10/site-packages/django/db/models/query.py", line 1790, in _insert
    return query.get_compiler(using=using).execute_sql(returning_fields)
  File "/home/wz/anaconda3/envs/coadd_env/lib/python3.10/site-packages/django/db/models/sql/compiler.py", line 1657, in execute_sql
    cursor.execute(sql, params)
  File "/home/wz/anaconda3/envs/coadd_env/lib/python3.10/site-packages/django/db/backends/utils.py", line 103, in execute
    return super().execute(sql, params)
  File "/home/wz/anaconda3/envs/coadd_env/lib/python3.10/site-packages/django/db/backends/utils.py", line 67, in execute
    return self._execute_with_wrappers(
  File "/home/wz/anaconda3/envs/coadd_env/lib/python3.10/site-packages/django/db/backends/utils.py", line 80, in _execute_with_wrappers
    return executor(sql, params, many, context)
  File "/home/wz/anaconda3/envs/coadd_env/lib/python3.10/site-packages/django/db/backends/utils.py", line 84, in _execute
    with self.db.wrap_database_errors:
  File "/home/wz/anaconda3/envs/coadd_env/lib/python3.10/site-packages/django/db/utils.py", line 91, in __exit__
    raise dj_exc_value.with_traceback(traceback) from exc_value
  File "/home/wz/anaconda3/envs/coadd_env/lib/python3.10/site-packages/django/db/backends/utils.py", line 89, in _execute
    return self.cursor.execute(sql, params)
django.db.utils.IntegrityError: null value in column "urlname" violates not-null constraint
DETAIL:  Failing row contains (0, 2023-02-05 11:09:00.994572+00, null, null, test, test, test, orgdb, null, null, null).

"POST /admin/apputil/dictionary/add/ HTTP/1.1" 500 200637
Not Found: /favicon.ico
"GET /favicon.ico HTTP/1.1" 404 11457
Not Found: /dict/dict_delete
"POST /dict/dict_delete HTTP/1.1" 404 11651
Not Found: /dict_delete
"POST /dict_delete HTTP/1.1" 404 4430
Not Found: /dict_delete
"POST /dict_delete HTTP/1.1" 404 4430
