Not Found: /favicon.ico
"GET /favicon.ico HTTP/1.1" 404 11284
Not Found: /favicon.ico
"GET /favicon.ico HTTP/1.1" 404 11284
Not Found: /json_demo_html_table.php
"POST /json_demo_html_table.php HTTP/1.1" 404 11324
Not Found: /json_demo_html_table.php
"POST /json_demo_html_table.php HTTP/1.1" 404 11324
Not Found: /json_demo_html_table.php
"POST /json_demo_html_table.php HTTP/1.1" 404 11324
Not Found: /json_demo_html_table.php
"GET /json_demo_html_table.php HTTP/1.1" 404 11323
Not Found: /favicon.ico
"GET /favicon.ico HTTP/1.1" 404 11284
Internal Server Error: /import-VITEK/
Traceback (most recent call last):
  File "/home/wz/anaconda3/envs/coadd_env/lib/python3.10/site-packages/django/core/handlers/exception.py", line 55, in inner
    response = get_response(request)
  File "/home/wz/anaconda3/envs/coadd_env/lib/python3.10/site-packages/django/core/handlers/base.py", line 197, in _get_response
    response = wrapped_callback(request, *callback_args, **callback_kwargs)
  File "/home/wz/anaconda3/envs/coadd_env/lib/python3.10/site-packages/django/views/generic/base.py", line 103, in view
    return self.dispatch(request, *args, **kwargs)
  File "/home/wz/anaconda3/envs/coadd_env/lib/python3.10/site-packages/django/contrib/auth/mixins.py", line 73, in dispatch
    return super().dispatch(request, *args, **kwargs)
  File "/home/wz/anaconda3/envs/coadd_env/lib/python3.10/site-packages/django/contrib/auth/mixins.py", line 135, in dispatch
    return super().dispatch(request, *args, **kwargs)
  File "/home/wz/anaconda3/envs/coadd_env/lib/python3.10/site-packages/django/views/generic/base.py", line 142, in dispatch
    return handler(request, *args, **kwargs)
  File "/home/wz/adjCOADD/apputil/utils_dataimport.py", line 119, in get
    filesinUploads_list=[file for file in os.listdir(self.dirname) if os.file.isfile(os.path.join(self.dirname, file))]
  File "/home/wz/adjCOADD/apputil/utils_dataimport.py", line 119, in <listcomp>
    filesinUploads_list=[file for file in os.listdir(self.dirname) if os.file.isfile(os.path.join(self.dirname, file))]
AttributeError: module 'os' has no attribute 'file'
"GET /import-VITEK/ HTTP/1.1" 500 93967
Internal Server Error: /import-VITEK/
Traceback (most recent call last):
  File "/home/wz/anaconda3/envs/coadd_env/lib/python3.10/site-packages/django/core/handlers/exception.py", line 55, in inner
    response = get_response(request)
  File "/home/wz/anaconda3/envs/coadd_env/lib/python3.10/site-packages/django/core/handlers/base.py", line 197, in _get_response
    response = wrapped_callback(request, *callback_args, **callback_kwargs)
  File "/home/wz/anaconda3/envs/coadd_env/lib/python3.10/site-packages/django/views/generic/base.py", line 103, in view
    return self.dispatch(request, *args, **kwargs)
  File "/home/wz/anaconda3/envs/coadd_env/lib/python3.10/site-packages/django/contrib/auth/mixins.py", line 73, in dispatch
    return super().dispatch(request, *args, **kwargs)
  File "/home/wz/anaconda3/envs/coadd_env/lib/python3.10/site-packages/django/contrib/auth/mixins.py", line 135, in dispatch
    return super().dispatch(request, *args, **kwargs)
  File "/home/wz/anaconda3/envs/coadd_env/lib/python3.10/site-packages/django/views/generic/base.py", line 142, in dispatch
    return handler(request, *args, **kwargs)
  File "/home/wz/adjCOADD/apputil/utils_dataimport.py", line 121, in get
    return render(request, 'ddrug/importhandler_vitek.html', { 'form': form, 'file_pathlist':filesinUploads_list})
NameError: name 'render' is not defined
"GET /import-VITEK/ HTTP/1.1" 500 94574
Internal Server Error: /import-VITEK/
Traceback (most recent call last):
  File "/home/wz/anaconda3/envs/coadd_env/lib/python3.10/site-packages/django/core/handlers/exception.py", line 55, in inner
    response = get_response(request)
  File "/home/wz/anaconda3/envs/coadd_env/lib/python3.10/site-packages/django/core/handlers/base.py", line 197, in _get_response
    response = wrapped_callback(request, *callback_args, **callback_kwargs)
  File "/home/wz/anaconda3/envs/coadd_env/lib/python3.10/site-packages/django/views/generic/base.py", line 103, in view
    return self.dispatch(request, *args, **kwargs)
  File "/home/wz/anaconda3/envs/coadd_env/lib/python3.10/site-packages/django/contrib/auth/mixins.py", line 73, in dispatch
    return super().dispatch(request, *args, **kwargs)
  File "/home/wz/anaconda3/envs/coadd_env/lib/python3.10/site-packages/django/contrib/auth/mixins.py", line 135, in dispatch
    return super().dispatch(request, *args, **kwargs)
  File "/home/wz/anaconda3/envs/coadd_env/lib/python3.10/site-packages/django/views/generic/base.py", line 142, in dispatch
    return handler(request, *args, **kwargs)
  File "/home/wz/adjCOADD/ddrug/views.py", line 212, in post
    context['file_pathlist']=filesinUploads_list
NameError: name 'filesinUploads_list' is not defined
"POST /import-VITEK/ HTTP/1.1" 500 90749
Internal Server Error: /import-VITEK/
Traceback (most recent call last):
  File "/home/wz/anaconda3/envs/coadd_env/lib/python3.10/site-packages/django/core/handlers/exception.py", line 55, in inner
    response = get_response(request)
  File "/home/wz/anaconda3/envs/coadd_env/lib/python3.10/site-packages/django/core/handlers/base.py", line 197, in _get_response
    response = wrapped_callback(request, *callback_args, **callback_kwargs)
  File "/home/wz/anaconda3/envs/coadd_env/lib/python3.10/site-packages/django/views/generic/base.py", line 103, in view
    return self.dispatch(request, *args, **kwargs)
  File "/home/wz/anaconda3/envs/coadd_env/lib/python3.10/site-packages/django/contrib/auth/mixins.py", line 73, in dispatch
    return super().dispatch(request, *args, **kwargs)
  File "/home/wz/anaconda3/envs/coadd_env/lib/python3.10/site-packages/django/contrib/auth/mixins.py", line 135, in dispatch
    return super().dispatch(request, *args, **kwargs)
  File "/home/wz/anaconda3/envs/coadd_env/lib/python3.10/site-packages/django/views/generic/base.py", line 142, in dispatch
    return handler(request, *args, **kwargs)
  File "/home/wz/adjCOADD/ddrug/views.py", line 269, in post
    self.validatefile_name.append[f]
TypeError: 'builtin_function_or_method' object is not subscriptable
"POST /import-VITEK/ HTTP/1.1" 500 92228
Internal Server Error: /import-VITEK/
Traceback (most recent call last):
  File "/home/wz/anaconda3/envs/coadd_env/lib/python3.10/site-packages/django/core/handlers/exception.py", line 55, in inner
    response = get_response(request)
  File "/home/wz/anaconda3/envs/coadd_env/lib/python3.10/site-packages/django/core/handlers/base.py", line 197, in _get_response
    response = wrapped_callback(request, *callback_args, **callback_kwargs)
  File "/home/wz/anaconda3/envs/coadd_env/lib/python3.10/site-packages/django/views/generic/base.py", line 103, in view
    return self.dispatch(request, *args, **kwargs)
  File "/home/wz/anaconda3/envs/coadd_env/lib/python3.10/site-packages/django/contrib/auth/mixins.py", line 73, in dispatch
    return super().dispatch(request, *args, **kwargs)
  File "/home/wz/anaconda3/envs/coadd_env/lib/python3.10/site-packages/django/contrib/auth/mixins.py", line 135, in dispatch
    return super().dispatch(request, *args, **kwargs)
  File "/home/wz/anaconda3/envs/coadd_env/lib/python3.10/site-packages/django/views/generic/base.py", line 142, in dispatch
    return handler(request, *args, **kwargs)
  File "/home/wz/adjCOADD/ddrug/views.py", line 298, in post
    validates(self.lCards, VITEK_Card, self.vLog, self.validate_result, self.file_report)
  File "/home/wz/adjCOADD/ddrug/views.py", line 293, in validates
    if rreport_filelog.get(key, None):
NameError: name 'rreport_filelog' is not defined
"POST /import-VITEK/ HTTP/1.1" 500 108807
Internal Server Error: /import-VITEK/
Traceback (most recent call last):
  File "/home/wz/anaconda3/envs/coadd_env/lib/python3.10/site-packages/django/core/handlers/exception.py", line 55, in inner
    response = get_response(request)
  File "/home/wz/anaconda3/envs/coadd_env/lib/python3.10/site-packages/django/core/handlers/base.py", line 197, in _get_response
    response = wrapped_callback(request, *callback_args, **callback_kwargs)
  File "/home/wz/anaconda3/envs/coadd_env/lib/python3.10/site-packages/django/views/generic/base.py", line 103, in view
    return self.dispatch(request, *args, **kwargs)
  File "/home/wz/anaconda3/envs/coadd_env/lib/python3.10/site-packages/django/contrib/auth/mixins.py", line 73, in dispatch
    return super().dispatch(request, *args, **kwargs)
  File "/home/wz/anaconda3/envs/coadd_env/lib/python3.10/site-packages/django/contrib/auth/mixins.py", line 135, in dispatch
    return super().dispatch(request, *args, **kwargs)
  File "/home/wz/anaconda3/envs/coadd_env/lib/python3.10/site-packages/django/views/generic/base.py", line 142, in dispatch
    return handler(request, *args, **kwargs)
  File "/home/wz/adjCOADD/ddrug/views.py", line 300, in post
    validates(self.lAst, VITEK_AST, self.vLog, self.validate_result, self.file_report)
  File "/home/wz/adjCOADD/ddrug/views.py", line 290, in validates
    report_result[key].append(str(app_model._meta.db_table)+str(djCard.validStatus))
AttributeError: 'str' object has no attribute 'append'
"POST /import-VITEK/ HTTP/1.1" 500 115681
Internal Server Error: /import-VITEK/
Traceback (most recent call last):
  File "/home/wz/anaconda3/envs/coadd_env/lib/python3.10/site-packages/django/core/handlers/exception.py", line 55, in inner
    response = get_response(request)
  File "/home/wz/anaconda3/envs/coadd_env/lib/python3.10/site-packages/django/core/handlers/base.py", line 197, in _get_response
    response = wrapped_callback(request, *callback_args, **callback_kwargs)
  File "/home/wz/anaconda3/envs/coadd_env/lib/python3.10/site-packages/django/views/generic/base.py", line 103, in view
    return self.dispatch(request, *args, **kwargs)
  File "/home/wz/anaconda3/envs/coadd_env/lib/python3.10/site-packages/django/contrib/auth/mixins.py", line 73, in dispatch
    return super().dispatch(request, *args, **kwargs)
  File "/home/wz/anaconda3/envs/coadd_env/lib/python3.10/site-packages/django/contrib/auth/mixins.py", line 135, in dispatch
    return super().dispatch(request, *args, **kwargs)
  File "/home/wz/anaconda3/envs/coadd_env/lib/python3.10/site-packages/django/views/generic/base.py", line 142, in dispatch
    return handler(request, *args, **kwargs)
  File "/home/wz/adjCOADD/ddrug/views.py", line 386, in post
    validates(self.lCards, VITEK_Card, self.vLog, self.validate_result, self.file_report, save=False, **kwargs)
NameError: name 'validates' is not defined
"POST /import-VITEK/ HTTP/1.1" 500 92297
Internal Server Error: /import-VITEK/
Traceback (most recent call last):
  File "/home/wz/adjCOADD/ddrug/views.py", line 300, in post
    vCards, vID, vAst=process_VitekPDF(DirName=self.dirname, PdfName=f)
  File "/home/wz/adjCOADD/ddrug/Vitek.py", line 339, in process_VitekPDF
    pVitek = parse_VitekPDF(DirName,PdfName)
  File "/home/wz/adjCOADD/ddrug/Vitek.py", line 21, in parse_VitekPDF
    with pdfplumber.open(os.path.join(DirName,PdfName)) as pdf:
  File "/home/wz/anaconda3/envs/coadd_env/lib/python3.10/site-packages/pdfplumber/pdf.py", line 71, in open
    stream = open(path_or_fp, "rb")
FileNotFoundError: [Errno 2] No such file or directory: '/home/wz/uploads/2023-02-01 22:02:53_user_test_Isolate_GN0963B001NP-2_GN96_EUCAST.pdf'

During handling of the above exception, another exception occurred:

Traceback (most recent call last):
  File "/home/wz/anaconda3/envs/coadd_env/lib/python3.10/site-packages/django/core/handlers/exception.py", line 55, in inner
    response = get_response(request)
  File "/home/wz/anaconda3/envs/coadd_env/lib/python3.10/site-packages/django/core/handlers/base.py", line 197, in _get_response
    response = wrapped_callback(request, *callback_args, **callback_kwargs)
  File "/home/wz/anaconda3/envs/coadd_env/lib/python3.10/site-packages/django/views/generic/base.py", line 103, in view
    return self.dispatch(request, *args, **kwargs)
  File "/home/wz/anaconda3/envs/coadd_env/lib/python3.10/site-packages/django/contrib/auth/mixins.py", line 73, in dispatch
    return super().dispatch(request, *args, **kwargs)
  File "/home/wz/anaconda3/envs/coadd_env/lib/python3.10/site-packages/django/contrib/auth/mixins.py", line 135, in dispatch
    return super().dispatch(request, *args, **kwargs)
  File "/home/wz/anaconda3/envs/coadd_env/lib/python3.10/site-packages/django/views/generic/base.py", line 142, in dispatch
    return handler(request, *args, **kwargs)
  File "/home/wz/adjCOADD/ddrug/views.py", line 306, in post
    self.delete_file(file_name=filename)
UnboundLocalError: local variable 'filename' referenced before assignment
"POST /import-VITEK/ HTTP/1.1" 500 111782
Internal Server Error: /import-VITEK/
Traceback (most recent call last):
  File "/home/wz/adjCOADD/ddrug/views.py", line 300, in post
    vCards, vID, vAst=process_VitekPDF(DirName=self.dirname, PdfName=f)
  File "/home/wz/adjCOADD/ddrug/Vitek.py", line 339, in process_VitekPDF
    pVitek = parse_VitekPDF(DirName,PdfName)
  File "/home/wz/adjCOADD/ddrug/Vitek.py", line 21, in parse_VitekPDF
    with pdfplumber.open(os.path.join(DirName,PdfName)) as pdf:
  File "/home/wz/anaconda3/envs/coadd_env/lib/python3.10/site-packages/pdfplumber/pdf.py", line 71, in open
    stream = open(path_or_fp, "rb")
FileNotFoundError: [Errno 2] No such file or directory: '/home/wz/uploads/2023-02-01 22:02:53_user_test_Isolate_GN0963B001NP-2_GN96_EUCAST.pdf'

During handling of the above exception, another exception occurred:

Traceback (most recent call last):
  File "/home/wz/anaconda3/envs/coadd_env/lib/python3.10/site-packages/django/core/handlers/exception.py", line 55, in inner
    response = get_response(request)
  File "/home/wz/anaconda3/envs/coadd_env/lib/python3.10/site-packages/django/core/handlers/base.py", line 197, in _get_response
    response = wrapped_callback(request, *callback_args, **callback_kwargs)
  File "/home/wz/anaconda3/envs/coadd_env/lib/python3.10/site-packages/django/views/generic/base.py", line 103, in view
    return self.dispatch(request, *args, **kwargs)
  File "/home/wz/anaconda3/envs/coadd_env/lib/python3.10/site-packages/django/contrib/auth/mixins.py", line 73, in dispatch
    return super().dispatch(request, *args, **kwargs)
  File "/home/wz/anaconda3/envs/coadd_env/lib/python3.10/site-packages/django/contrib/auth/mixins.py", line 135, in dispatch
    return super().dispatch(request, *args, **kwargs)
  File "/home/wz/anaconda3/envs/coadd_env/lib/python3.10/site-packages/django/views/generic/base.py", line 142, in dispatch
    return handler(request, *args, **kwargs)
  File "/home/wz/adjCOADD/ddrug/views.py", line 307, in post
    messages.warning(request, f'{filename} contains {err} erro , cannot to upload, choose a correct file')
UnboundLocalError: local variable 'filename' referenced before assignment
"POST /import-VITEK/ HTTP/1.1" 500 111941
Internal Server Error: /import-VITEK/
Traceback (most recent call last):
  File "/home/wz/anaconda3/envs/coadd_env/lib/python3.10/site-packages/django/core/handlers/exception.py", line 55, in inner
    response = get_response(request)
  File "/home/wz/anaconda3/envs/coadd_env/lib/python3.10/site-packages/django/core/handlers/base.py", line 197, in _get_response
    response = wrapped_callback(request, *callback_args, **callback_kwargs)
  File "/home/wz/anaconda3/envs/coadd_env/lib/python3.10/site-packages/django/views/generic/base.py", line 103, in view
    return self.dispatch(request, *args, **kwargs)
  File "/home/wz/anaconda3/envs/coadd_env/lib/python3.10/site-packages/django/contrib/auth/mixins.py", line 73, in dispatch
    return super().dispatch(request, *args, **kwargs)
  File "/home/wz/anaconda3/envs/coadd_env/lib/python3.10/site-packages/django/contrib/auth/mixins.py", line 135, in dispatch
    return super().dispatch(request, *args, **kwargs)
  File "/home/wz/anaconda3/envs/coadd_env/lib/python3.10/site-packages/django/views/generic/base.py", line 142, in dispatch
    return handler(request, *args, **kwargs)
  File "/home/wz/adjCOADD/ddrug/views.py", line 311, in post
    self.validates(self.lCards, VITEK_Card, self.vLog, self.validate_result, self.file_report, save=False, **kwargs)
  File "/home/wz/adjCOADD/ddrug/views.py", line 207, in validates
    print(**kwargs)
TypeError: 'user' is an invalid keyword argument for print()
"POST /import-VITEK/ HTTP/1.1" 500 106121
Internal Server Error: /import-VITEK/
Traceback (most recent call last):
  File "/home/wz/anaconda3/envs/coadd_env/lib/python3.10/site-packages/django/core/handlers/exception.py", line 55, in inner
    response = get_response(request)
  File "/home/wz/anaconda3/envs/coadd_env/lib/python3.10/site-packages/django/core/handlers/base.py", line 197, in _get_response
    response = wrapped_callback(request, *callback_args, **callback_kwargs)
  File "/home/wz/anaconda3/envs/coadd_env/lib/python3.10/site-packages/django/views/generic/base.py", line 103, in view
    return self.dispatch(request, *args, **kwargs)
  File "/home/wz/anaconda3/envs/coadd_env/lib/python3.10/site-packages/django/contrib/auth/mixins.py", line 73, in dispatch
    return super().dispatch(request, *args, **kwargs)
  File "/home/wz/anaconda3/envs/coadd_env/lib/python3.10/site-packages/django/contrib/auth/mixins.py", line 135, in dispatch
    return super().dispatch(request, *args, **kwargs)
  File "/home/wz/anaconda3/envs/coadd_env/lib/python3.10/site-packages/django/views/generic/base.py", line 142, in dispatch
    return handler(request, *args, **kwargs)
  File "/home/wz/adjCOADD/ddrug/views.py", line 312, in post
    self.validates(self.lCards, VITEK_Card, self.vLog, self.validate_result, self.file_report, save=False, **kwargs)
  File "/home/wz/adjCOADD/ddrug/views.py", line 208, in validates
    print(kwargs[user])
NameError: name 'user' is not defined
"POST /import-VITEK/ HTTP/1.1" 500 107782
